Workbook

Sheet Method
A1: ECS DERIVATION METHOD — CANONICAL · ST_ECS_Derivation_Method_v1
A2: Status | B2: CANONICAL — author sign-off June 2026. Restores the derivation chain previously attributed to ST_ECS_v1.xlsx (file absent from corpus).
A4: FORMULA | B4: ECS = 100 × (1 − C / 34)
A5: C (Conflict Score) | B5: Sum over 17 resources of pairwise conflict points between the two environments’ Net Effect values.
A6: Conflict points per resource | B6: 2 = direct opposition (+ vs −) · 1 = partial (+ vs ~ or − vs ~) · 0 = identical Net Effect (including ~/~, +/+, −/−)
A7: Denominator 34 | B7: Maximum possible conflict: 17 resources × 2 points.
A8: Rounding | B8: One decimal place. All canonical matrix values are exact multiples of 100/34 ≈ 2.941.
A9: Symmetry | B9: The formula is symmetric: ECS(A,B) = ECS(B,A). Directionality (acquirer vs target) is carried exclusively by the friction-point narratives, never by the score.
A11: DATA SOURCE | B11: Net Effect column, sheet "Resource Impact Matrix", in each of the 9 Environment Reference files (NF_NT, NF_SFJ, NF_SFP, NT_STJ, NT_STP, SFJ_SFP, SFP_SFJ, STJ_STP, STP_STJ _Environment_Reference.xlsx). Mirrored on sheet Net_Effect_Vectors of this file; the Reference files remain the single source of truth.
A12: REPRODUCTION PROOF | B12: Sheet Reproduction_Test: all 28 published pair scores in ST_Friction_Point_Lookup_updated.xlsx → ECS_Matrix reproduced with 0.0 deviation. Verified June 2026.
A13: AUDIT ENTRY POINT | B13: An independent analyst verifies three things: (1) Net Effect vectors match the Reference files; (2) per-resource conflict formulas on Pair_Computation; (3) Reproduction_Test = 28/28 PASS.
A15: SUPERSESSION NOTE | B15: This file supersedes the narrative-only description on sheet Derivation_Method of ST_Friction_Point_Lookup_updated.xlsx for the ECS-score layer. Friction-point narrative derivation remains documented there.
A17: SCORE INTERPRETATION RULE | B17: Canonical home: sheet Interpretation_Caveats of this file (author decision, June 2026). No standalone Score Interpretation Rule file exists in canon.

Sheet Net_Effect_Vectors
A1: Environment | B1: Time | C1: Energy | D1: Attention | E1: Money | F1: Reputation | G1: Trust | H1: Influence | I1: Information | J1: Connections | K1: Skills | L1: Knowledge | M1: Health | N1: Psychological resilience | O1: Will / discipline | P1: Creativity | Q1: Decisiveness | R1: Organisation / system
A2: NF/NT | B2: + | C2: + | D2: + | E2: ~ | F2: + | G2: + | H2: + | I2: + | J2: + | K2: + | L2: + | M2: ~ | N2: + | O2: + | P2: + | Q2: ~ | R2: ~
A3: NF/SFJ | B3: - | C3: - | D3: - | E3: - | F3: ~ | G3: - | H3: - | I3: - | J3: ~ | K3: - | L3: - | M3: - | N3: - | O3: - | P3: - | Q3: - | R3: -
A4: NF/SFP | B4: ~ | C4: + | D4: + | E4: ~ | F4: + | G4: + | H4: + | I4: ~ | J4: + | K4: + | L4: ~ | M4: + | N4: + | O4: ~ | P4: + | Q4: ~ | R4: -
A5: NT/STJ | B5: + | C5: + | D5: + | E5: + | F5: + | G5: ~ | H5: + | I5: + | J5: ~ | K5: + | L5: + | M5: ~ | N5: + | O5: + | P5: + | Q5: + | R5: +
A6: NT/STP | B6: ~ | C6: + | D6: + | E6: ~ | F6: + | G6: ~ | H6: + | I6: + | J6: ~ | K6: + | L6: + | M6: ~ | N6: + | O6: + | P6: + | Q6: + | R6: ~
A7: SFJ/SFP | B7: + | C7: + | D7: + | E7: + | F7: + | G7: + | H7: + | I7: ~ | J7: + | K7: + | L7: - | M7: + | N7: + | O7: - | P7: - | Q7: - | R7: -
A8: SFP/SFJ | B8: - | C8: ~ | D8: - | E8: - | F8: - | G8: - | H8: - | I8: - | J8: - | K8: - | L8: - | M8: - | N8: - | O8: - | P8: - | Q8: - | R8: ~
A9: STJ/STP | B9: ~ | C9: + | D9: ~ | E9: + | F9: + | G9: - | H9: + | I9: ~ | J9: ~ | K9: + | L9: - | M9: ~ | N9: ~ | O9: + | P9: ~ | Q9: + | R9: +
A10: STP/STJ | B10: ~ | C10: + | D10: + | E10: + | F10: + | G10: - | H10: + | I10: ~ | J10: + | K10: + | L10: - | M10: - | N10: ~ | O10: + | P10: ~ | Q10: + | R10: +
A12: Source: "Resource Impact Matrix" sheet, Net Effect column, of each *_Environment_Reference.xlsx. Verbatim mirror, June 2026.

Sheet Pair_Computation
A1: Env A | B1: Env B | C1: Time | D1: Energy | E1: Attention | F1: Money | G1: Reputation | H1: Trust | I1: Influence | J1: Information | K1: Connections | L1: Skills | M1: Knowledge | N1: Health | O1: Psychological resilience | P1: Will / discipline | Q1: Creativity | R1: Decisiveness | S1: Organisation / system | T1: C (conflict) | U1: ECS | V1: Band | W1: Status
A2: NF/NT | B2: NF/SFJ | C2: =IF(INDEX(Net_Effect_Vectors!$B$2:$R$10,MATCH($A2,Net_Effect_Vectors!$A$2:$A$10,0),COLUMN()-2)=INDEX(Net_Effect_Vectors!$B$2:$R$10,MATCH($B2,Net_Effect_Vectors!$A$2:$A$10,0),COLUMN()-2),0,IF(OR(INDEX(Net_Effect_Vectors!$B$2:$R$10,MATCH($A2,Net_Effect_Vectors!$A$2:$A$10,0),COLUMN()-2)="~",INDEX(Net_Effect_Vectors!$B$2:$R$10,MATCH($B2,Net_Effect_Vectors!$A$2:$A$10,0),COLUMN()-2)="~"),1,2)) -> 2 | D2: =IF(INDEX(Net_Effect_Vectors!$B$2:$R$10,MATCH($A2,Net_Effect_Vectors!$A$2:$A$10,0),COLUMN()-2)=INDEX(Net_Effect_Vectors!$B$2:$R$10,MATCH($B2,Net_Effect_Vectors!$A$2:$A$10,0),COLUMN()-2),0,IF(OR(INDEX(Net_Effect_Vectors!$B$2:$R$10,MATCH($A2,Net_Effect_Vectors!$A$2:$A$10,0),COLUMN()-2)="~",INDEX(Net_Effect_Vectors!$B$2:$R$10,MATCH($B2,Net_Effect_Vectors!$A$2:$A$10,0),COLUMN()-2)="~"),1,2)) -> 2 | E2: =IF(INDEX(Net_Effect_Vectors!$B$2:$R$10,MATCH($A2,Net_Effect_Vectors!$A$2:$A$10,0),COLUMN()-2)=INDEX(Net_Effect_Vectors!$B$2:$R$10,MATCH($B2,Net_Effect_Vectors!$A$2:$A$10,0),COLUMN()-2),0,IF(OR(INDEX(Net_Effect_Vectors!$B$2:$R$10,MATCH($A2,Net_Effect_Vectors!$A$2:$A$10,0),COLUMN()-2)="~",INDEX(Net_Effect_Vectors!$B$2:$R$10,MATCH($B2,Net_Effect_Vectors!$A$2:$A$10,0),COLUMN()-2)="~"),1,2)) -> 2 | F2: =IF(INDEX(Net_Effect_Vectors!$B$2:$R$10,MATCH($A2,Net_Effect_Vectors!$A$2:$A$10,0),COLUMN()-2)=INDEX(Net_Effect_Vectors!$B$2:$R$10,MATCH($B2,Net_Effect_Vectors!$A$2:$A$10,0),COLUMN()-2),0,IF(OR(INDEX(Net_Effect_Vectors!$B$2:$R$10,MATCH($A2,Net_Effect_Vectors!$A$2:$A$10,0),COLUMN()-2)="~",INDEX(Net_Effect_Vectors!$B$2:$R$10,MATCH($B2,Net_Effect_Vectors!$A$2:$A$10,0),COLUMN()-2)="~"),1,2)) -> 1 | G2: =IF(INDEX(Net_Effect_Vectors!$B$2:$R$10,MATCH($A2,Net_Effect_Vectors!$A$2:$A$10,0),COLUMN()-2)=INDEX(Net_Effect_Vectors!$B$2:$R$10,MATCH($B2,Net_Effect_Vectors!$A$2:$A$10,0),COLUMN()-2),0,IF(OR(INDEX(Net_Effect_Vectors!$B$2:$R$10,MATCH($A2,Net_Effect_Vectors!$A$2:$A$10,0),COLUMN()-2)="~",INDEX(Net_Effect_Vectors!$B$2:$R$10,MATCH($B2,Net_Effect_Vectors!$A$2:$A$10,0),COLUMN()-2)="~"),1,2)) -> 1 | H2: =IF(INDEX(Net_Effect_Vectors!$B$2:$R$10,MATCH($A2,Net_Effect_Vectors!$A$2:$A$10,0),COLUMN()-2)=INDEX(Net_Effect_Vectors!$B$2:$R$10,MATCH($B2,Net_Effect_Vectors!$A$2:$A$10,0),COLUMN()-2),0,IF(OR(INDEX(Net_Effect_Vectors!$B$2:$R$10,MATCH($A2,Net_Effect_Vectors!$A$2:$A$10,0),COLUMN()-2)="~",INDEX(Net_Effect_Vectors!$B$2:$R$10,MATCH($B2,Net_Effect_Vectors!$A$2:$A$10,0),COLUMN()-2)="~"),1,2)) -> 2 | I2: =IF(INDEX(Net_Effect_Vectors!$B$2:$R$10,MATCH($A2,Net_Effect_Vectors!$A$2:$A$10,0),COLUMN()-2)=INDEX(Net_Effect_Vectors!$B$2:$R$10,MATCH($B2,Net_Effect_Vectors!$A$2:$A$10,0),COLUMN()-2),0,IF(OR(INDEX(Net_Effect_Vectors!$B$2:$R$10,MATCH($A2,Net_Effect_Vectors!$A$2:$A$10,0),COLUMN()-2)="~",INDEX(Net_Effect_Vectors!$B$2:$R$10,MATCH($B2,Net_Effect_Vectors!$A$2:$A$10,0),COLUMN()-2)="~"),1,2)) -> 2 | J2: =IF(INDEX(Net_Effect_Vectors!$B$2:$R$10,MATCH($A2,Net_Effect_Vectors!$A$2:$A$10,0),COLUMN()-2)=INDEX(Net_Effect_Vectors!$B$2:$R$10,MATCH($B2,Net_Effect_Vectors!$A$2:$A$10,0),COLUMN()-2),0,IF(OR(INDEX(Net_Effect_Vectors!$B$2:$R$10,MATCH($A2,Net_Effect_Vectors!$A$2:$A$10,0),COLUMN()-2)="~",INDEX(Net_Effect_Vectors!$B$2:$R$10,MATCH($B2,Net_Effect_Vectors!$A$2:$A$10,0),COLUMN()-2)="~"),1,2)) -> 2 | ... S2: =IF(INDEX(Net_Effect_Vectors!$B$2:$R$10,MATCH($A2,Net_Effect_Vectors!$A$2:$A$10,0),COLUMN()-2)=INDEX(Net_Effect_Vectors!$B$2:$R$10,MATCH($B2,Net_Effect_Vectors!$A$2:$A$10,0),COLUMN()-2),0,IF(OR(INDEX(Net_Effect_Vectors!$B$2:$R$10,MATCH($A2,Net_Effect_Vectors!$A$2:$A$10,0),COLUMN()-2)="~",INDEX(Net_Effect_Vectors!$B$2:$R$10,MATCH($B2,Net_Effect_Vectors!$A$2:$A$10,0),COLUMN()-2)="~"),1,2)) -> 1 | T2: =SUM(C2:S2) -> 28 | U2: =ROUND(100*(1-T2/34),1) -> 17.6 | V2: =IF(U2>=80,"HIGH COMPATIBILITY",IF(U2>=65,"MODERATE-HIGH",IF(U2>=50,"MODERATE",IF(U2>=35,"MODERATE-LOW","HIGH RISK")))) -> HIGH RISK | W2: CANON (reproduced)
A3: NF/NT | B3: NF/SFP | C3: =IF(INDEX(Net_Effect_Vectors!$B$2:$R$10,MATCH($A3,Net_Effect_Vectors!$A$2:$A$10,0),COLUMN()-2)=INDEX(Net_Effect_Vectors!$B$2:$R$10,MATCH($B3,Net_Effect_Vectors!$A$2:$A$10,0),COLUMN()-2),0,IF(OR(INDEX(Net_Effect_Vectors!$B$2:$R$10,MATCH($A3,Net_Effect_Vectors!$A$2:$A$10,0),COLUMN()-2)="~",INDEX(Net_Effect_Vectors!$B$2:$R$10,MATCH($B3,Net_Effect_Vectors!$A$2:$A$10,0),COLUMN()-2)="~"),1,2)) -> 1 | D3: =IF(INDEX(Net_Effect_Vectors!$B$2:$R$10,MATCH($A3,Net_Effect_Vectors!$A$2:$A$10,0),COLUMN()-2)=INDEX(Net_Effect_Vectors!$B$2:$R$10,MATCH($B3,Net_Effect_Vectors!$A$2:$A$10,0),COLUMN()-2),0,IF(OR(INDEX(Net_Effect_Vectors!$B$2:$R$10,MATCH($A3,Net_Effect_Vectors!$A$2:$A$10,0),COLUMN()-2)="~",INDEX(Net_Effect_Vectors!$B$2:$R$10,MATCH($B3,Net_Effect_Vectors!$A$2:$A$10,0),COLUMN()-2)="~"),1,2)) -> 0 | E3: =IF(INDEX(Net_Effect_Vectors!$B$2:$R$10,MATCH($A3,Net_Effect_Vectors!$A$2:$A$10,0),COLUMN()-2)=INDEX(Net_Effect_Vectors!$B$2:$R$10,MATCH($B3,Net_Effect_Vectors!$A$2:$A$10,0),COLUMN()-2),0,IF(OR(INDEX(Net_Effect_Vectors!$B$2:$R$10,MATCH($A3,Net_Effect_Vectors!$A$2:$A$10,0),COLUMN()-2)="~",INDEX(Net_Effect_Vectors!$B$2:$R$10,MATCH($B3,Net_Effect_Vectors!$A$2:$A$10,0),COLUMN()-2)="~"),1,2)) -> 0 | F3: =IF(INDEX(Net_Effect_Vectors!$B$2:$R$10,MATCH($A3,Net_Effect_Vectors!$A$2:$A$10,0),COLUMN()-2)=INDEX(Net_Effect_Vectors!$B$2:$R$10,MATCH($B3,Net_Effect_Vectors!$A$2:$A$10,0),COLUMN()-2),0,IF(OR(INDEX(Net_Effect_Vectors!$B$2:$R$10,MATCH($A3,Net_Effect_Vectors!$A$2:$A$10,0),COLUMN()-2)="~",INDEX(Net_Effect_Vectors!$B$2:$R$10,MATCH($B3,Net_Effect_Vectors!$A$2:$A$10,0),COLUMN()-2)="~"),1,2)) -> 0 | G3: =IF(INDEX(Net_Effect_Vectors!$B$2:$R$10,MATCH($A3,Net_Effect_Vectors!$A$2:$A$10,0),COLUMN()-2)=INDEX(Net_Effect_Vectors!$B$2:$R$10,MATCH($B3,Net_Effect_Vectors!$A$2:$A$10,0),COLUMN()-2),0,IF(OR(INDEX(Net_Effect_Vectors!$B$2:$R$10,MATCH($A3,Net_Effect_Vectors!$A$2:$A$10,0),COLUMN()-2)="~",INDEX(Net_Effect_Vectors!$B$2:$R$10,MATCH($B3,Net_Effect_Vectors!$A$2:$A$10,0),COLUMN()-2)="~"),1,2)) -> 0 | H3: =IF(INDEX(Net_Effect_Vectors!$B$2:$R$10,MATCH($A3,Net_Effect_Vectors!$A$2:$A$10,0),COLUMN()-2)=INDEX(Net_Effect_Vectors!$B$2:$R$10,MATCH($B3,Net_Effect_Vectors!$A$2:$A$10,0),COLUMN()-2),0,IF(OR(INDEX(Net_Effect_Vectors!$B$2:$R$10,MATCH($A3,Net_Effect_Vectors!$A$2:$A$10,0),COLUMN()-2)="~",INDEX(Net_Effect_Vectors!$B$2:$R$10,MATCH($B3,Net_Effect_Vectors!$A$2:$A$10,0),COLUMN()-2)="~"),1,2)) -> 0 | I3: =IF(INDEX(Net_Effect_Vectors!$B$2:$R$10,MATCH($A3,Net_Effect_Vectors!$A$2:$A$10,0),COLUMN()-2)=INDEX(Net_Effect_Vectors!$B$2:$R$10,MATCH($B3,Net_Effect_Vectors!$A$2:$A$10,0),COLUMN()-2),0,IF(OR(INDEX(Net_Effect_Vectors!$B$2:$R$10,MATCH($A3,Net_Effect_Vectors!$A$2:$A$10,0),COLUMN()-2)="~",INDEX(Net_Effect_Vectors!$B$2:$R$10,MATCH($B3,Net_Effect_Vectors!$A$2:$A$10,0),COLUMN()-2)="~"),1,2)) -> 0 | J3: =IF(INDEX(Net_Effect_Vectors!$B$2:$R$10,MATCH($A3,Net_Effect_Vectors!$A$2:$A$10,0),COLUMN()-2)=INDEX(Net_Effect_Vectors!$B$2:$R$10,MATCH($B3,Net_Effect_Vectors!$A$2:$A$10,0),COLUMN()-2),0,IF(OR(INDEX(Net_Effect_Vectors!$B$2:$R$10,MATCH($A3,Net_Effect_Vectors!$A$2:$A$10,0),COLUMN()-2)="~",INDEX(Net_Effect_Vectors!$B$2:$R$10,MATCH($B3,Net_Effect_Vectors!$A$2:$A$10,0),COLUMN()-2)="~"),1,2)) -> 1 | ... S3: =IF(INDEX(Net_Effect_Vectors!$B$2:$R$10,MATCH($A3,Net_Effect_Vectors!$A$2:$A$10,0),COLUMN()-2)=INDEX(Net_Effect_Vectors!$B$2:$R$10,MATCH($B3,Net_Effect_Vectors!$A$2:$A$10,0),COLUMN()-2),0,IF(OR(INDEX(Net_Effect_Vectors!$B$2:$R$10,MATCH($A3,Net_Effect_Vectors!$A$2:$A$10,0),COLUMN()-2)="~",INDEX(Net_Effect_Vectors!$B$2:$R$10,MATCH($B3,Net_Effect_Vectors!$A$2:$A$10,0),COLUMN()-2)="~"),1,2)) -> 1 | T3: =SUM(C3:S3) -> 6 | U3: =ROUND(100*(1-T3/34),1) -> 82.4 | V3: =IF(U3>=80,"HIGH COMPATIBILITY",IF(U3>=65,"MODERATE-HIGH",IF(U3>=50,"MODERATE",IF(U3>=35,"MODERATE-LOW","HIGH RISK")))) -> HIGH COMPATIBILITY | W3: CANON (reproduced)
A4: NF/NT | B4: NT/STJ | C4: =IF(INDEX(Net_Effect_Vectors!$B$2:$R$10,MATCH($A4,Net_Effect_Vectors!$A$2:$A$10,0),COLUMN()-2)=INDEX(Net_Effect_Vectors!$B$2:$R$10,MATCH($B4,Net_Effect_Vectors!$A$2:$A$10,0),COLUMN()-2),0,IF(OR(INDEX(Net_Effect_Vectors!$B$2:$R$10,MATCH($A4,Net_Effect_Vectors!$A$2:$A$10,0),COLUMN()-2)="~",INDEX(Net_Effect_Vectors!$B$2:$R$10,MATCH($B4,Net_Effect_Vectors!$A$2:$A$10,0),COLUMN()-2)="~"),1,2)) -> 0 | D4: =IF(INDEX(Net_Effect_Vectors!$B$2:$R$10,MATCH($A4,Net_Effect_Vectors!$A$2:$A$10,0),COLUMN()-2)=INDEX(Net_Effect_Vectors!$B$2:$R$10,MATCH($B4,Net_Effect_Vectors!$A$2:$A$10,0),COLUMN()-2),0,IF(OR(INDEX(Net_Effect_Vectors!$B$2:$R$10,MATCH($A4,Net_Effect_Vectors!$A$2:$A$10,0),COLUMN()-2)="~",INDEX(Net_Effect_Vectors!$B$2:$R$10,MATCH($B4,Net_Effect_Vectors!$A$2:$A$10,0),COLUMN()-2)="~"),1,2)) -> 0 | E4: =IF(INDEX(Net_Effect_Vectors!$B$2:$R$10,MATCH($A4,Net_Effect_Vectors!$A$2:$A$10,0),COLUMN()-2)=INDEX(Net_Effect_Vectors!$B$2:$R$10,MATCH($B4,Net_Effect_Vectors!$A$2:$A$10,0),COLUMN()-2),0,IF(OR(INDEX(Net_Effect_Vectors!$B$2:$R$10,MATCH($A4,Net_Effect_Vectors!$A$2:$A$10,0),COLUMN()-2)="~",INDEX(Net_Effect_Vectors!$B$2:$R$10,MATCH($B4,Net_Effect_Vectors!$A$2:$A$10,0),COLUMN()-2)="~"),1,2)) -> 0 | F4: =IF(INDEX(Net_Effect_Vectors!$B$2:$R$10,MATCH($A4,Net_Effect_Vectors!$A$2:$A$10,0),COLUMN()-2)=INDEX(Net_Effect_Vectors!$B$2:$R$10,MATCH($B4,Net_Effect_Vectors!$A$2:$A$10,0),COLUMN()-2),0,IF(OR(INDEX(Net_Effect_Vectors!$B$2:$R$10,MATCH($A4,Net_Effect_Vectors!$A$2:$A$10,0),COLUMN()-2)="~",INDEX(Net_Effect_Vectors!$B$2:$R$10,MATCH($B4,Net_Effect_Vectors!$A$2:$A$10,0),COLUMN()-2)="~"),1,2)) -> 1 | G4: =IF(INDEX(Net_Effect_Vectors!$B$2:$R$10,MATCH($A4,Net_Effect_Vectors!$A$2:$A$10,0),COLUMN()-2)=INDEX(Net_Effect_Vectors!$B$2:$R$10,MATCH($B4,Net_Effect_Vectors!$A$2:$A$10,0),COLUMN()-2),0,IF(OR(INDEX(Net_Effect_Vectors!$B$2:$R$10,MATCH($A4,Net_Effect_Vectors!$A$2:$A$10,0),COLUMN()-2)="~",INDEX(Net_Effect_Vectors!$B$2:$R$10,MATCH($B4,Net_Effect_Vectors!$A$2:$A$10,0),COLUMN()-2)="~"),1,2)) -> 0 | H4: =IF(INDEX(Net_Effect_Vectors!$B$2:$R$10,MATCH($A4,Net_Effect_Vectors!$A$2:$A$10,0),COLUMN()-2)=INDEX(Net_Effect_Vectors!$B$2:$R$10,MATCH($B4,Net_Effect_Vectors!$A$2:$A$10,0),COLUMN()-2),0,IF(OR(INDEX(Net_Effect_Vectors!$B$2:$R$10,MATCH($A4,Net_Effect_Vectors!$A$2:$A$10,0),COLUMN()-2)="~",INDEX(Net_Effect_Vectors!$B$2:$R$10,MATCH($B4,Net_Effect_Vectors!$A$2:$A$10,0),COLUMN()-2)="~"),1,2)) -> 1 | I4: =IF(INDEX(Net_Effect_Vectors!$B$2:$R$10,MATCH($A4,Net_Effect_Vectors!$A$2:$A$10,0),COLUMN()-2)=INDEX(Net_Effect_Vectors!$B$2:$R$10,MATCH($B4,Net_Effect_Vectors!$A$2:$A$10,0),COLUMN()-2),0,IF(OR(INDEX(Net_Effect_Vectors!$B$2:$R$10,MATCH($A4,Net_Effect_Vectors!$A$2:$A$10,0),COLUMN()-2)="~",INDEX(Net_Effect_Vectors!$B$2:$R$10,MATCH($B4,Net_Effect_Vectors!$A$2:$A$10,0),COLUMN()-2)="~"),1,2)) -> 0 | J4: =IF(INDEX(Net_Effect_Vectors!$B$2:$R$10,MATCH($A4,Net_Effect_Vectors!$A$2:$A$10,0),COLUMN()-2)=INDEX(Net_Effect_Vectors!$B$2:$R$10,MATCH($B4,Net_Effect_Vectors!$A$2:$A$10,0),COLUMN()-2),0,IF(OR(INDEX(Net_Effect_Vectors!$B$2:$R$10,MATCH($A4,Net_Effect_Vectors!$A$2:$A$10,0),COLUMN()-2)="~",INDEX(Net_Effect_Vectors!$B$2:$R$10,MATCH($B4,Net_Effect_Vectors!$A$2:$A$10,0),COLUMN()-2)="~"),1,2)) -> 0 | ... S4: =IF(INDEX(Net_Effect_Vectors!$B$2:$R$10,MATCH($A4,Net_Effect_Vectors!$A$2:$A$10,0),COLUMN()-2)=INDEX(Net_Effect_Vectors!$B$2:$R$10,MATCH($B4,Net_Effect_Vectors!$A$2:$A$10,0),COLUMN()-2),0,IF(OR(INDEX(Net_Effect_Vectors!$B$2:$R$10,MATCH($A4,Net_Effect_Vectors!$A$2:$A$10,0),COLUMN()-2)="~",INDEX(Net_Effect_Vectors!$B$2:$R$10,MATCH($B4,Net_Effect_Vectors!$A$2:$A$10,0),COLUMN()-2)="~"),1,2)) -> 1 | T4: =SUM(C4:S4) -> 5 | U4: =ROUND(100*(1-T4/34),1) -> 85.3 | V4: =IF(U4>=80,"HIGH COMPATIBILITY",IF(U4>=65,"MODERATE-HIGH",IF(U4>=50,"MODERATE",IF(U4>=35,"MODERATE-LOW","HIGH RISK")))) -> HIGH COMPATIBILITY | W4: CANON (reproduced)
A5: NF/NT | B5: NT/STP | C5: =IF(INDEX(Net_Effect_Vectors!$B$2:$R$10,MATCH($A5,Net_Effect_Vectors!$A$2:$A$10,0),COLUMN()-2)=INDEX(Net_Effect_Vectors!$B$2:$R$10,MATCH($B5,Net_Effect_Vectors!$A$2:$A$10,0),COLUMN()-2),0,IF(OR(INDEX(Net_Effect_Vectors!$B$2:$R$10,MATCH($A5,Net_Effect_Vectors!$A$2:$A$10,0),COLUMN()-2)="~",INDEX(Net_Effect_Vectors!$B$2:$R$10,MATCH($B5,Net_Effect_Vectors!$A$2:$A$10,0),COLUMN()-2)="~"),1,2)) -> 1 | D5: =IF(INDEX(Net_Effect_Vectors!$B$2:$R$10,MATCH($A5,Net_Effect_Vectors!$A$2:$A$10,0),COLUMN()-2)=INDEX(Net_Effect_Vectors!$B$2:$R$10,MATCH($B5,Net_Effect_Vectors!$A$2:$A$10,0),COLUMN()-2),0,IF(OR(INDEX(Net_Effect_Vectors!$B$2:$R$10,MATCH($A5,Net_Effect_Vectors!$A$2:$A$10,0),COLUMN()-2)="~",INDEX(Net_Effect_Vectors!$B$2:$R$10,MATCH($B5,Net_Effect_Vectors!$A$2:$A$10,0),COLUMN()-2)="~"),1,2)) -> 0 | E5: =IF(INDEX(Net_Effect_Vectors!$B$2:$R$10,MATCH($A5,Net_Effect_Vectors!$A$2:$A$10,0),COLUMN()-2)=INDEX(Net_Effect_Vectors!$B$2:$R$10,MATCH($B5,Net_Effect_Vectors!$A$2:$A$10,0),COLUMN()-2),0,IF(OR(INDEX(Net_Effect_Vectors!$B$2:$R$10,MATCH($A5,Net_Effect_Vectors!$A$2:$A$10,0),COLUMN()-2)="~",INDEX(Net_Effect_Vectors!$B$2:$R$10,MATCH($B5,Net_Effect_Vectors!$A$2:$A$10,0),COLUMN()-2)="~"),1,2)) -> 0 | F5: =IF(INDEX(Net_Effect_Vectors!$B$2:$R$10,MATCH($A5,Net_Effect_Vectors!$A$2:$A$10,0),COLUMN()-2)=INDEX(Net_Effect_Vectors!$B$2:$R$10,MATCH($B5,Net_Effect_Vectors!$A$2:$A$10,0),COLUMN()-2),0,IF(OR(INDEX(Net_Effect_Vectors!$B$2:$R$10,MATCH($A5,Net_Effect_Vectors!$A$2:$A$10,0),COLUMN()-2)="~",INDEX(Net_Effect_Vectors!$B$2:$R$10,MATCH($B5,Net_Effect_Vectors!$A$2:$A$10,0),COLUMN()-2)="~"),1,2)) -> 0 | G5: =IF(INDEX(Net_Effect_Vectors!$B$2:$R$10,MATCH($A5,Net_Effect_Vectors!$A$2:$A$10,0),COLUMN()-2)=INDEX(Net_Effect_Vectors!$B$2:$R$10,MATCH($B5,Net_Effect_Vectors!$A$2:$A$10,0),COLUMN()-2),0,IF(OR(INDEX(Net_Effect_Vectors!$B$2:$R$10,MATCH($A5,Net_Effect_Vectors!$A$2:$A$10,0),COLUMN()-2)="~",INDEX(Net_Effect_Vectors!$B$2:$R$10,MATCH($B5,Net_Effect_Vectors!$A$2:$A$10,0),COLUMN()-2)="~"),1,2)) -> 0 | H5: =IF(INDEX(Net_Effect_Vectors!$B$2:$R$10,MATCH($A5,Net_Effect_Vectors!$A$2:$A$10,0),COLUMN()-2)=INDEX(Net_Effect_Vectors!$B$2:$R$10,MATCH($B5,Net_Effect_Vectors!$A$2:$A$10,0),COLUMN()-2),0,IF(OR(INDEX(Net_Effect_Vectors!$B$2:$R$10,MATCH($A5,Net_Effect_Vectors!$A$2:$A$10,0),COLUMN()-2)="~",INDEX(Net_Effect_Vectors!$B$2:$R$10,MATCH($B5,Net_Effect_Vectors!$A$2:$A$10,0),COLUMN()-2)="~"),1,2)) -> 1 | I5: =IF(INDEX(Net_Effect_Vectors!$B$2:$R$10,MATCH($A5,Net_Effect_Vectors!$A$2:$A$10,0),COLUMN()-2)=INDEX(Net_Effect_Vectors!$B$2:$R$10,MATCH($B5,Net_Effect_Vectors!$A$2:$A$10,0),COLUMN()-2),0,IF(OR(INDEX(Net_Effect_Vectors!$B$2:$R$10,MATCH($A5,Net_Effect_Vectors!$A$2:$A$10,0),COLUMN()-2)="~",INDEX(Net_Effect_Vectors!$B$2:$R$10,MATCH($B5,Net_Effect_Vectors!$A$2:$A$10,0),COLUMN()-2)="~"),1,2)) -> 0 | J5: =IF(INDEX(Net_Effect_Vectors!$B$2:$R$10,MATCH($A5,Net_Effect_Vectors!$A$2:$A$10,0),COLUMN()-2)=INDEX(Net_Effect_Vectors!$B$2:$R$10,MATCH($B5,Net_Effect_Vectors!$A$2:$A$10,0),COLUMN()-2),0,IF(OR(INDEX(Net_Effect_Vectors!$B$2:$R$10,MATCH($A5,Net_Effect_Vectors!$A$2:$A$10,0),COLUMN()-2)="~",INDEX(Net_Effect_Vectors!$B$2:$R$10,MATCH($B5,Net_Effect_Vectors!$A$2:$A$10,0),COLUMN()-2)="~"),1,2)) -> 0 | ... S5: =IF(INDEX(Net_Effect_Vectors!$B$2:$R$10,MATCH($A5,Net_Effect_Vectors!$A$2:$A$10,0),COLUMN()-2)=INDEX(Net_Effect_Vectors!$B$2:$R$10,MATCH($B5,Net_Effect_Vectors!$A$2:$A$10,0),COLUMN()-2),0,IF(OR(INDEX(Net_Effect_Vectors!$B$2:$R$10,MATCH($A5,Net_Effect_Vectors!$A$2:$A$10,0),COLUMN()-2)="~",INDEX(Net_Effect_Vectors!$B$2:$R$10,MATCH($B5,Net_Effect_Vectors!$A$2:$A$10,0),COLUMN()-2)="~"),1,2)) -> 0 | T5: =SUM(C5:S5) -> 4 | U5: =ROUND(100*(1-T5/34),1) -> 88.2 | V5: =IF(U5>=80,"HIGH COMPATIBILITY",IF(U5>=65,"MODERATE-HIGH",IF(U5>=50,"MODERATE",IF(U5>=35,"MODERATE-LOW","HIGH RISK")))) -> HIGH COMPATIBILITY | W5: CANON (reproduced)
A6: NF/NT | B6: SFJ/SFP | C6: =IF(INDEX(Net_Effect_Vectors!$B$2:$R$10,MATCH($A6,Net_Effect_Vectors!$A$2:$A$10,0),COLUMN()-2)=INDEX(Net_Effect_Vectors!$B$2:$R$10,MATCH($B6,Net_Effect_Vectors!$A$2:$A$10,0),COLUMN()-2),0,IF(OR(INDEX(Net_Effect_Vectors!$B$2:$R$10,MATCH($A6,Net_Effect_Vectors!$A$2:$A$10,0),COLUMN()-2)="~",INDEX(Net_Effect_Vectors!$B$2:$R$10,MATCH($B6,Net_Effect_Vectors!$A$2:$A$10,0),COLUMN()-2)="~"),1,2)) -> 0 | D6: =IF(INDEX(Net_Effect_Vectors!$B$2:$R$10,MATCH($A6,Net_Effect_Vectors!$A$2:$A$10,0),COLUMN()-2)=INDEX(Net_Effect_Vectors!$B$2:$R$10,MATCH($B6,Net_Effect_Vectors!$A$2:$A$10,0),COLUMN()-2),0,IF(OR(INDEX(Net_Effect_Vectors!$B$2:$R$10,MATCH($A6,Net_Effect_Vectors!$A$2:$A$10,0),COLUMN()-2)="~",INDEX(Net_Effect_Vectors!$B$2:$R$10,MATCH($B6,Net_Effect_Vectors!$A$2:$A$10,0),COLUMN()-2)="~"),1,2)) -> 0 | E6: =IF(INDEX(Net_Effect_Vectors!$B$2:$R$10,MATCH($A6,Net_Effect_Vectors!$A$2:$A$10,0),COLUMN()-2)=INDEX(Net_Effect_Vectors!$B$2:$R$10,MATCH($B6,Net_Effect_Vectors!$A$2:$A$10,0),COLUMN()-2),0,IF(OR(INDEX(Net_Effect_Vectors!$B$2:$R$10,MATCH($A6,Net_Effect_Vectors!$A$2:$A$10,0),COLUMN()-2)="~",INDEX(Net_Effect_Vectors!$B$2:$R$10,MATCH($B6,Net_Effect_Vectors!$A$2:$A$10,0),COLUMN()-2)="~"),1,2)) -> 0 | F6: =IF(INDEX(Net_Effect_Vectors!$B$2:$R$10,MATCH($A6,Net_Effect_Vectors!$A$2:$A$10,0),COLUMN()-2)=INDEX(Net_Effect_Vectors!$B$2:$R$10,MATCH($B6,Net_Effect_Vectors!$A$2:$A$10,0),COLUMN()-2),0,IF(OR(INDEX(Net_Effect_Vectors!$B$2:$R$10,MATCH($A6,Net_Effect_Vectors!$A$2:$A$10,0),COLUMN()-2)="~",INDEX(Net_Effect_Vectors!$B$2:$R$10,MATCH($B6,Net_Effect_Vectors!$A$2:$A$10,0),COLUMN()-2)="~"),1,2)) -> 1 | G6: =IF(INDEX(Net_Effect_Vectors!$B$2:$R$10,MATCH($A6,Net_Effect_Vectors!$A$2:$A$10,0),COLUMN()-2)=INDEX(Net_Effect_Vectors!$B$2:$R$10,MATCH($B6,Net_Effect_Vectors!$A$2:$A$10,0),COLUMN()-2),0,IF(OR(INDEX(Net_Effect_Vectors!$B$2:$R$10,MATCH($A6,Net_Effect_Vectors!$A$2:$A$10,0),COLUMN()-2)="~",INDEX(Net_Effect_Vectors!$B$2:$R$10,MATCH($B6,Net_Effect_Vectors!$A$2:$A$10,0),COLUMN()-2)="~"),1,2)) -> 0 | H6: =IF(INDEX(Net_Effect_Vectors!$B$2:$R$10,MATCH($A6,Net_Effect_Vectors!$A$2:$A$10,0),COLUMN()-2)=INDEX(Net_Effect_Vectors!$B$2:$R$10,MATCH($B6,Net_Effect_Vectors!$A$2:$A$10,0),COLUMN()-2),0,IF(OR(INDEX(Net_Effect_Vectors!$B$2:$R$10,MATCH($A6,Net_Effect_Vectors!$A$2:$A$10,0),COLUMN()-2)="~",INDEX(Net_Effect_Vectors!$B$2:$R$10,MATCH($B6,Net_Effect_Vectors!$A$2:$A$10,0),COLUMN()-2)="~"),1,2)) -> 0 | I6: =IF(INDEX(Net_Effect_Vectors!$B$2:$R$10,MATCH($A6,Net_Effect_Vectors!$A$2:$A$10,0),COLUMN()-2)=INDEX(Net_Effect_Vectors!$B$2:$R$10,MATCH($B6,Net_Effect_Vectors!$A$2:$A$10,0),COLUMN()-2),0,IF(OR(INDEX(Net_Effect_Vectors!$B$2:$R$10,MATCH($A6,Net_Effect_Vectors!$A$2:$A$10,0),COLUMN()-2)="~",INDEX(Net_Effect_Vectors!$B$2:$R$10,MATCH($B6,Net_Effect_Vectors!$A$2:$A$10,0),COLUMN()-2)="~"),1,2)) -> 0 | J6: =IF(INDEX(Net_Effect_Vectors!$B$2:$R$10,MATCH($A6,Net_Effect_Vectors!$A$2:$A$10,0),COLUMN()-2)=INDEX(Net_Effect_Vectors!$B$2:$R$10,MATCH($B6,Net_Effect_Vectors!$A$2:$A$10,0),COLUMN()-2),0,IF(OR(INDEX(Net_Effect_Vectors!$B$2:$R$10,MATCH($A6,Net_Effect_Vectors!$A$2:$A$10,0),COLUMN()-2)="~",INDEX(Net_Effect_Vectors!$B$2:$R$10,MATCH($B6,Net_Effect_Vectors!$A$2:$A$10,0),COLUMN()-2)="~"),1,2)) -> 1 | ... S6: =IF(INDEX(Net_Effect_Vectors!$B$2:$R$10,MATCH($A6,Net_Effect_Vectors!$A$2:$A$10,0),COLUMN()-2)=INDEX(Net_Effect_Vectors!$B$2:$R$10,MATCH($B6,Net_Effect_Vectors!$A$2:$A$10,0),COLUMN()-2),0,IF(OR(INDEX(Net_Effect_Vectors!$B$2:$R$10,MATCH($A6,Net_Effect_Vectors!$A$2:$A$10,0),COLUMN()-2)="~",INDEX(Net_Effect_Vectors!$B$2:$R$10,MATCH($B6,Net_Effect_Vectors!$A$2:$A$10,0),COLUMN()-2)="~"),1,2)) -> 1 | T6: =SUM(C6:S6) -> 11 | U6: =ROUND(100*(1-T6/34),1) -> 67.6 | V6: =IF(U6>=80,"HIGH COMPATIBILITY",IF(U6>=65,"MODERATE-HIGH",IF(U6>=50,"MODERATE",IF(U6>=35,"MODERATE-LOW","HIGH RISK")))) -> MODERATE-HIGH | W6: CANON (reproduced)
A7: NF/NT | B7: SFP/SFJ | C7: =IF(INDEX(Net_Effect_Vectors!$B$2:$R$10,MATCH($A7,Net_Effect_Vectors!$A$2:$A$10,0),COLUMN()-2)=INDEX(Net_Effect_Vectors!$B$2:$R$10,MATCH($B7,Net_Effect_Vectors!$A$2:$A$10,0),COLUMN()-2),0,IF(OR(INDEX(Net_Effect_Vectors!$B$2:$R$10,MATCH($A7,Net_Effect_Vectors!$A$2:$A$10,0),COLUMN()-2)="~",INDEX(Net_Effect_Vectors!$B$2:$R$10,MATCH($B7,Net_Effect_Vectors!$A$2:$A$10,0),COLUMN()-2)="~"),1,2)) -> 2 | D7: =IF(INDEX(Net_Effect_Vectors!$B$2:$R$10,MATCH($A7,Net_Effect_Vectors!$A$2:$A$10,0),COLUMN()-2)=INDEX(Net_Effect_Vectors!$B$2:$R$10,MATCH($B7,Net_Effect_Vectors!$A$2:$A$10,0),COLUMN()-2),0,IF(OR(INDEX(Net_Effect_Vectors!$B$2:$R$10,MATCH($A7,Net_Effect_Vectors!$A$2:$A$10,0),COLUMN()-2)="~",INDEX(Net_Effect_Vectors!$B$2:$R$10,MATCH($B7,Net_Effect_Vectors!$A$2:$A$10,0),COLUMN()-2)="~"),1,2)) -> 1 | E7: =IF(INDEX(Net_Effect_Vectors!$B$2:$R$10,MATCH($A7,Net_Effect_Vectors!$A$2:$A$10,0),COLUMN()-2)=INDEX(Net_Effect_Vectors!$B$2:$R$10,MATCH($B7,Net_Effect_Vectors!$A$2:$A$10,0),COLUMN()-2),0,IF(OR(INDEX(Net_Effect_Vectors!$B$2:$R$10,MATCH($A7,Net_Effect_Vectors!$A$2:$A$10,0),COLUMN()-2)="~",INDEX(Net_Effect_Vectors!$B$2:$R$10,MATCH($B7,Net_Effect_Vectors!$A$2:$A$10,0),COLUMN()-2)="~"),1,2)) -> 2 | F7: =IF(INDEX(Net_Effect_Vectors!$B$2:$R$10,MATCH($A7,Net_Effect_Vectors!$A$2:$A$10,0),COLUMN()-2)=INDEX(Net_Effect_Vectors!$B$2:$R$10,MATCH($B7,Net_Effect_Vectors!$A$2:$A$10,0),COLUMN()-2),0,IF(OR(INDEX(Net_Effect_Vectors!$B$2:$R$10,MATCH($A7,Net_Effect_Vectors!$A$2:$A$10,0),COLUMN()-2)="~",INDEX(Net_Effect_Vectors!$B$2:$R$10,MATCH($B7,Net_Effect_Vectors!$A$2:$A$10,0),COLUMN()-2)="~"),1,2)) -> 1 | G7: =IF(INDEX(Net_Effect_Vectors!$B$2:$R$10,MATCH($A7,Net_Effect_Vectors!$A$2:$A$10,0),COLUMN()-2)=INDEX(Net_Effect_Vectors!$B$2:$R$10,MATCH($B7,Net_Effect_Vectors!$A$2:$A$10,0),COLUMN()-2),0,IF(OR(INDEX(Net_Effect_Vectors!$B$2:$R$10,MATCH($A7,Net_Effect_Vectors!$A$2:$A$10,0),COLUMN()-2)="~",INDEX(Net_Effect_Vectors!$B$2:$R$10,MATCH($B7,Net_Effect_Vectors!$A$2:$A$10,0),COLUMN()-2)="~"),1,2)) -> 2 | H7: =IF(INDEX(Net_Effect_Vectors!$B$2:$R$10,MATCH($A7,Net_Effect_Vectors!$A$2:$A$10,0),COLUMN()-2)=INDEX(Net_Effect_Vectors!$B$2:$R$10,MATCH($B7,Net_Effect_Vectors!$A$2:$A$10,0),COLUMN()-2),0,IF(OR(INDEX(Net_Effect_Vectors!$B$2:$R$10,MATCH($A7,Net_Effect_Vectors!$A$2:$A$10,0),COLUMN()-2)="~",INDEX(Net_Effect_Vectors!$B$2:$R$10,MATCH($B7,Net_Effect_Vectors!$A$2:$A$10,0),COLUMN()-2)="~"),1,2)) -> 2 | I7: =IF(INDEX(Net_Effect_Vectors!$B$2:$R$10,MATCH($A7,Net_Effect_Vectors!$A$2:$A$10,0),COLUMN()-2)=INDEX(Net_Effect_Vectors!$B$2:$R$10,MATCH($B7,Net_Effect_Vectors!$A$2:$A$10,0),COLUMN()-2),0,IF(OR(INDEX(Net_Effect_Vectors!$B$2:$R$10,MATCH($A7,Net_Effect_Vectors!$A$2:$A$10,0),COLUMN()-2)="~",INDEX(Net_Effect_Vectors!$B$2:$R$10,MATCH($B7,Net_Effect_Vectors!$A$2:$A$10,0),COLUMN()-2)="~"),1,2)) -> 2 | J7: =IF(INDEX(Net_Effect_Vectors!$B$2:$R$10,MATCH($A7,Net_Effect_Vectors!$A$2:$A$10,0),COLUMN()-2)=INDEX(Net_Effect_Vectors!$B$2:$R$10,MATCH($B7,Net_Effect_Vectors!$A$2:$A$10,0),COLUMN()-2),0,IF(OR(INDEX(Net_Effect_Vectors!$B$2:$R$10,MATCH($A7,Net_Effect_Vectors!$A$2:$A$10,0),COLUMN()-2)="~",INDEX(Net_Effect_Vectors!$B$2:$R$10,MATCH($B7,Net_Effect_Vectors!$A$2:$A$10,0),COLUMN()-2)="~"),1,2)) -> 2 | ... S7: =IF(INDEX(Net_Effect_Vectors!$B$2:$R$10,MATCH($A7,Net_Effect_Vectors!$A$2:$A$10,0),COLUMN()-2)=INDEX(Net_Effect_Vectors!$B$2:$R$10,MATCH($B7,Net_Effect_Vectors!$A$2:$A$10,0),COLUMN()-2),0,IF(OR(INDEX(Net_Effect_Vectors!$B$2:$R$10,MATCH($A7,Net_Effect_Vectors!$A$2:$A$10,0),COLUMN()-2)="~",INDEX(Net_Effect_Vectors!$B$2:$R$10,MATCH($B7,Net_Effect_Vectors!$A$2:$A$10,0),COLUMN()-2)="~"),1,2)) -> 0 | T7: =SUM(C7:S7) -> 28 | U7: =ROUND(100*(1-T7/34),1) -> 17.6 | V7: =IF(U7>=80,"HIGH COMPATIBILITY",IF(U7>=65,"MODERATE-HIGH",IF(U7>=50,"MODERATE",IF(U7>=35,"MODERATE-LOW","HIGH RISK")))) -> HIGH RISK | W7: CANON (reproduced)
A8: NF/NT | B8: STJ/STP | C8: =IF(INDEX(Net_Effect_Vectors!$B$2:$R$10,MATCH($A8,Net_Effect_Vectors!$A$2:$A$10,0),COLUMN()-2)=INDEX(Net_Effect_Vectors!$B$2:$R$10,MATCH($B8,Net_Effect_Vectors!$A$2:$A$10,0),COLUMN()-2),0,IF(OR(INDEX(Net_Effect_Vectors!$B$2:$R$10,MATCH($A8,Net_Effect_Vectors!$A$2:$A$10,0),COLUMN()-2)="~",INDEX(Net_Effect_Vectors!$B$2:$R$10,MATCH($B8,Net_Effect_Vectors!$A$2:$A$10,0),COLUMN()-2)="~"),1,2)) -> 1 | D8: =IF(INDEX(Net_Effect_Vectors!$B$2:$R$10,MATCH($A8,Net_Effect_Vectors!$A$2:$A$10,0),COLUMN()-2)=INDEX(Net_Effect_Vectors!$B$2:$R$10,MATCH($B8,Net_Effect_Vectors!$A$2:$A$10,0),COLUMN()-2),0,IF(OR(INDEX(Net_Effect_Vectors!$B$2:$R$10,MATCH($A8,Net_Effect_Vectors!$A$2:$A$10,0),COLUMN()-2)="~",INDEX(Net_Effect_Vectors!$B$2:$R$10,MATCH($B8,Net_Effect_Vectors!$A$2:$A$10,0),COLUMN()-2)="~"),1,2)) -> 0 | E8: =IF(INDEX(Net_Effect_Vectors!$B$2:$R$10,MATCH($A8,Net_Effect_Vectors!$A$2:$A$10,0),COLUMN()-2)=INDEX(Net_Effect_Vectors!$B$2:$R$10,MATCH($B8,Net_Effect_Vectors!$A$2:$A$10,0),COLUMN()-2),0,IF(OR(INDEX(Net_Effect_Vectors!$B$2:$R$10,MATCH($A8,Net_Effect_Vectors!$A$2:$A$10,0),COLUMN()-2)="~",INDEX(Net_Effect_Vectors!$B$2:$R$10,MATCH($B8,Net_Effect_Vectors!$A$2:$A$10,0),COLUMN()-2)="~"),1,2)) -> 1 | F8: =IF(INDEX(Net_Effect_Vectors!$B$2:$R$10,MATCH($A8,Net_Effect_Vectors!$A$2:$A$10,0),COLUMN()-2)=INDEX(Net_Effect_Vectors!$B$2:$R$10,MATCH($B8,Net_Effect_Vectors!$A$2:$A$10,0),COLUMN()-2),0,IF(OR(INDEX(Net_Effect_Vectors!$B$2:$R$10,MATCH($A8,Net_Effect_Vectors!$A$2:$A$10,0),COLUMN()-2)="~",INDEX(Net_Effect_Vectors!$B$2:$R$10,MATCH($B8,Net_Effect_Vectors!$A$2:$A$10,0),COLUMN()-2)="~"),1,2)) -> 1 | G8: =IF(INDEX(Net_Effect_Vectors!$B$2:$R$10,MATCH($A8,Net_Effect_Vectors!$A$2:$A$10,0),COLUMN()-2)=INDEX(Net_Effect_Vectors!$B$2:$R$10,MATCH($B8,Net_Effect_Vectors!$A$2:$A$10,0),COLUMN()-2),0,IF(OR(INDEX(Net_Effect_Vectors!$B$2:$R$10,MATCH($A8,Net_Effect_Vectors!$A$2:$A$10,0),COLUMN()-2)="~",INDEX(Net_Effect_Vectors!$B$2:$R$10,MATCH($B8,Net_Effect_Vectors!$A$2:$A$10,0),COLUMN()-2)="~"),1,2)) -> 0 | H8: =IF(INDEX(Net_Effect_Vectors!$B$2:$R$10,MATCH($A8,Net_Effect_Vectors!$A$2:$A$10,0),COLUMN()-2)=INDEX(Net_Effect_Vectors!$B$2:$R$10,MATCH($B8,Net_Effect_Vectors!$A$2:$A$10,0),COLUMN()-2),0,IF(OR(INDEX(Net_Effect_Vectors!$B$2:$R$10,MATCH($A8,Net_Effect_Vectors!$A$2:$A$10,0),COLUMN()-2)="~",INDEX(Net_Effect_Vectors!$B$2:$R$10,MATCH($B8,Net_Effect_Vectors!$A$2:$A$10,0),COLUMN()-2)="~"),1,2)) -> 2 | I8: =IF(INDEX(Net_Effect_Vectors!$B$2:$R$10,MATCH($A8,Net_Effect_Vectors!$A$2:$A$10,0),COLUMN()-2)=INDEX(Net_Effect_Vectors!$B$2:$R$10,MATCH($B8,Net_Effect_Vectors!$A$2:$A$10,0),COLUMN()-2),0,IF(OR(INDEX(Net_Effect_Vectors!$B$2:$R$10,MATCH($A8,Net_Effect_Vectors!$A$2:$A$10,0),COLUMN()-2)="~",INDEX(Net_Effect_Vectors!$B$2:$R$10,MATCH($B8,Net_Effect_Vectors!$A$2:$A$10,0),COLUMN()-2)="~"),1,2)) -> 0 | J8: =IF(INDEX(Net_Effect_Vectors!$B$2:$R$10,MATCH($A8,Net_Effect_Vectors!$A$2:$A$10,0),COLUMN()-2)=INDEX(Net_Effect_Vectors!$B$2:$R$10,MATCH($B8,Net_Effect_Vectors!$A$2:$A$10,0),COLUMN()-2),0,IF(OR(INDEX(Net_Effect_Vectors!$B$2:$R$10,MATCH($A8,Net_Effect_Vectors!$A$2:$A$10,0),COLUMN()-2)="~",INDEX(Net_Effect_Vectors!$B$2:$R$10,MATCH($B8,Net_Effect_Vectors!$A$2:$A$10,0),COLUMN()-2)="~"),1,2)) -> 1 | ... S8: =IF(INDEX(Net_Effect_Vectors!$B$2:$R$10,MATCH($A8,Net_Effect_Vectors!$A$2:$A$10,0),COLUMN()-2)=INDEX(Net_Effect_Vectors!$B$2:$R$10,MATCH($B8,Net_Effect_Vectors!$A$2:$A$10,0),COLUMN()-2),0,IF(OR(INDEX(Net_Effect_Vectors!$B$2:$R$10,MATCH($A8,Net_Effect_Vectors!$A$2:$A$10,0),COLUMN()-2)="~",INDEX(Net_Effect_Vectors!$B$2:$R$10,MATCH($B8,Net_Effect_Vectors!$A$2:$A$10,0),COLUMN()-2)="~"),1,2)) -> 1 | T8: =SUM(C8:S8) -> 13 | U8: =ROUND(100*(1-T8/34),1) -> 61.8 | V8: =IF(U8>=80,"HIGH COMPATIBILITY",IF(U8>=65,"MODERATE-HIGH",IF(U8>=50,"MODERATE",IF(U8>=35,"MODERATE-LOW","HIGH RISK")))) -> MODERATE | W8: CANON (reproduced)
A9: NF/NT | B9: STP/STJ | C9: =IF(INDEX(Net_Effect_Vectors!$B$2:$R$10,MATCH($A9,Net_Effect_Vectors!$A$2:$A$10,0),COLUMN()-2)=INDEX(Net_Effect_Vectors!$B$2:$R$10,MATCH($B9,Net_Effect_Vectors!$A$2:$A$10,0),COLUMN()-2),0,IF(OR(INDEX(Net_Effect_Vectors!$B$2:$R$10,MATCH($A9,Net_Effect_Vectors!$A$2:$A$10,0),COLUMN()-2)="~",INDEX(Net_Effect_Vectors!$B$2:$R$10,MATCH($B9,Net_Effect_Vectors!$A$2:$A$10,0),COLUMN()-2)="~"),1,2)) -> 1 | D9: =IF(INDEX(Net_Effect_Vectors!$B$2:$R$10,MATCH($A9,Net_Effect_Vectors!$A$2:$A$10,0),COLUMN()-2)=INDEX(Net_Effect_Vectors!$B$2:$R$10,MATCH($B9,Net_Effect_Vectors!$A$2:$A$10,0),COLUMN()-2),0,IF(OR(INDEX(Net_Effect_Vectors!$B$2:$R$10,MATCH($A9,Net_Effect_Vectors!$A$2:$A$10,0),COLUMN()-2)="~",INDEX(Net_Effect_Vectors!$B$2:$R$10,MATCH($B9,Net_Effect_Vectors!$A$2:$A$10,0),COLUMN()-2)="~"),1,2)) -> 0 | E9: =IF(INDEX(Net_Effect_Vectors!$B$2:$R$10,MATCH($A9,Net_Effect_Vectors!$A$2:$A$10,0),COLUMN()-2)=INDEX(Net_Effect_Vectors!$B$2:$R$10,MATCH($B9,Net_Effect_Vectors!$A$2:$A$10,0),COLUMN()-2),0,IF(OR(INDEX(Net_Effect_Vectors!$B$2:$R$10,MATCH($A9,Net_Effect_Vectors!$A$2:$A$10,0),COLUMN()-2)="~",INDEX(Net_Effect_Vectors!$B$2:$R$10,MATCH($B9,Net_Effect_Vectors!$A$2:$A$10,0),COLUMN()-2)="~"),1,2)) -> 0 | F9: =IF(INDEX(Net_Effect_Vectors!$B$2:$R$10,MATCH($A9,Net_Effect_Vectors!$A$2:$A$10,0),COLUMN()-2)=INDEX(Net_Effect_Vectors!$B$2:$R$10,MATCH($B9,Net_Effect_Vectors!$A$2:$A$10,0),COLUMN()-2),0,IF(OR(INDEX(Net_Effect_Vectors!$B$2:$R$10,MATCH($A9,Net_Effect_Vectors!$A$2:$A$10,0),COLUMN()-2)="~",INDEX(Net_Effect_Vectors!$B$2:$R$10,MATCH($B9,Net_Effect_Vectors!$A$2:$A$10,0),COLUMN()-2)="~"),1,2)) -> 1 | G9: =IF(INDEX(Net_Effect_Vectors!$B$2:$R$10,MATCH($A9,Net_Effect_Vectors!$A$2:$A$10,0),COLUMN()-2)=INDEX(Net_Effect_Vectors!$B$2:$R$10,MATCH($B9,Net_Effect_Vectors!$A$2:$A$10,0),COLUMN()-2),0,IF(OR(INDEX(Net_Effect_Vectors!$B$2:$R$10,MATCH($A9,Net_Effect_Vectors!$A$2:$A$10,0),COLUMN()-2)="~",INDEX(Net_Effect_Vectors!$B$2:$R$10,MATCH($B9,Net_Effect_Vectors!$A$2:$A$10,0),COLUMN()-2)="~"),1,2)) -> 0 | H9: =IF(INDEX(Net_Effect_Vectors!$B$2:$R$10,MATCH($A9,Net_Effect_Vectors!$A$2:$A$10,0),COLUMN()-2)=INDEX(Net_Effect_Vectors!$B$2:$R$10,MATCH($B9,Net_Effect_Vectors!$A$2:$A$10,0),COLUMN()-2),0,IF(OR(INDEX(Net_Effect_Vectors!$B$2:$R$10,MATCH($A9,Net_Effect_Vectors!$A$2:$A$10,0),COLUMN()-2)="~",INDEX(Net_Effect_Vectors!$B$2:$R$10,MATCH($B9,Net_Effect_Vectors!$A$2:$A$10,0),COLUMN()-2)="~"),1,2)) -> 2 | I9: =IF(INDEX(Net_Effect_Vectors!$B$2:$R$10,MATCH($A9,Net_Effect_Vectors!$A$2:$A$10,0),COLUMN()-2)=INDEX(Net_Effect_Vectors!$B$2:$R$10,MATCH($B9,Net_Effect_Vectors!$A$2:$A$10,0),COLUMN()-2),0,IF(OR(INDEX(Net_Effect_Vectors!$B$2:$R$10,MATCH($A9,Net_Effect_Vectors!$A$2:$A$10,0),COLUMN()-2)="~",INDEX(Net_Effect_Vectors!$B$2:$R$10,MATCH($B9,Net_Effect_Vectors!$A$2:$A$10,0),COLUMN()-2)="~"),1,2)) -> 0 | J9: =IF(INDEX(Net_Effect_Vectors!$B$2:$R$10,MATCH($A9,Net_Effect_Vectors!$A$2:$A$10,0),COLUMN()-2)=INDEX(Net_Effect_Vectors!$B$2:$R$10,MATCH($B9,Net_Effect_Vectors!$A$2:$A$10,0),COLUMN()-2),0,IF(OR(INDEX(Net_Effect_Vectors!$B$2:$R$10,MATCH($A9,Net_Effect_Vectors!$A$2:$A$10,0),COLUMN()-2)="~",INDEX(Net_Effect_Vectors!$B$2:$R$10,MATCH($B9,Net_Effect_Vectors!$A$2:$A$10,0),COLUMN()-2)="~"),1,2)) -> 1 | ... S9: =IF(INDEX(Net_Effect_Vectors!$B$2:$R$10,MATCH($A9,Net_Effect_Vectors!$A$2:$A$10,0),COLUMN()-2)=INDEX(Net_Effect_Vectors!$B$2:$R$10,MATCH($B9,Net_Effect_Vectors!$A$2:$A$10,0),COLUMN()-2),0,IF(OR(INDEX(Net_Effect_Vectors!$B$2:$R$10,MATCH($A9,Net_Effect_Vectors!$A$2:$A$10,0),COLUMN()-2)="~",INDEX(Net_Effect_Vectors!$B$2:$R$10,MATCH($B9,Net_Effect_Vectors!$A$2:$A$10,0),COLUMN()-2)="~"),1,2)) -> 1 | T9: =SUM(C9:S9) -> 12 | U9: =ROUND(100*(1-T9/34),1) -> 64.7 | V9: =IF(U9>=80,"HIGH COMPATIBILITY",IF(U9>=65,"MODERATE-HIGH",IF(U9>=50,"MODERATE",IF(U9>=35,"MODERATE-LOW","HIGH RISK")))) -> MODERATE | W9: CANON (author-canonized June 2026)
A10: NF/SFJ | B10: NF/SFP | C10: =IF(INDEX(Net_Effect_Vectors!$B$2:$R$10,MATCH($A10,Net_Effect_Vectors!$A$2:$A$10,0),COLUMN()-2)=INDEX(Net_Effect_Vectors!$B$2:$R$10,MATCH($B10,Net_Effect_Vectors!$A$2:$A$10,0),COLUMN()-2),0,IF(OR(INDEX(Net_Effect_Vectors!$B$2:$R$10,MATCH($A10,Net_Effect_Vectors!$A$2:$A$10,0),COLUMN()-2)="~",INDEX(Net_Effect_Vectors!$B$2:$R$10,MATCH($B10,Net_Effect_Vectors!$A$2:$A$10,0),COLUMN()-2)="~"),1,2)) -> 1 | D10: =IF(INDEX(Net_Effect_Vectors!$B$2:$R$10,MATCH($A10,Net_Effect_Vectors!$A$2:$A$10,0),COLUMN()-2)=INDEX(Net_Effect_Vectors!$B$2:$R$10,MATCH($B10,Net_Effect_Vectors!$A$2:$A$10,0),COLUMN()-2),0,IF(OR(INDEX(Net_Effect_Vectors!$B$2:$R$10,MATCH($A10,Net_Effect_Vectors!$A$2:$A$10,0),COLUMN()-2)="~",INDEX(Net_Effect_Vectors!$B$2:$R$10,MATCH($B10,Net_Effect_Vectors!$A$2:$A$10,0),COLUMN()-2)="~"),1,2)) -> 2 | E10: =IF(INDEX(Net_Effect_Vectors!$B$2:$R$10,MATCH($A10,Net_Effect_Vectors!$A$2:$A$10,0),COLUMN()-2)=INDEX(Net_Effect_Vectors!$B$2:$R$10,MATCH($B10,Net_Effect_Vectors!$A$2:$A$10,0),COLUMN()-2),0,IF(OR(INDEX(Net_Effect_Vectors!$B$2:$R$10,MATCH($A10,Net_Effect_Vectors!$A$2:$A$10,0),COLUMN()-2)="~",INDEX(Net_Effect_Vectors!$B$2:$R$10,MATCH($B10,Net_Effect_Vectors!$A$2:$A$10,0),COLUMN()-2)="~"),1,2)) -> 2 | F10: =IF(INDEX(Net_Effect_Vectors!$B$2:$R$10,MATCH($A10,Net_Effect_Vectors!$A$2:$A$10,0),COLUMN()-2)=INDEX(Net_Effect_Vectors!$B$2:$R$10,MATCH($B10,Net_Effect_Vectors!$A$2:$A$10,0),COLUMN()-2),0,IF(OR(INDEX(Net_Effect_Vectors!$B$2:$R$10,MATCH($A10,Net_Effect_Vectors!$A$2:$A$10,0),COLUMN()-2)="~",INDEX(Net_Effect_Vectors!$B$2:$R$10,MATCH($B10,Net_Effect_Vectors!$A$2:$A$10,0),COLUMN()-2)="~"),1,2)) -> 1 | G10: =IF(INDEX(Net_Effect_Vectors!$B$2:$R$10,MATCH($A10,Net_Effect_Vectors!$A$2:$A$10,0),COLUMN()-2)=INDEX(Net_Effect_Vectors!$B$2:$R$10,MATCH($B10,Net_Effect_Vectors!$A$2:$A$10,0),COLUMN()-2),0,IF(OR(INDEX(Net_Effect_Vectors!$B$2:$R$10,MATCH($A10,Net_Effect_Vectors!$A$2:$A$10,0),COLUMN()-2)="~",INDEX(Net_Effect_Vectors!$B$2:$R$10,MATCH($B10,Net_Effect_Vectors!$A$2:$A$10,0),COLUMN()-2)="~"),1,2)) -> 1 | H10: =IF(INDEX(Net_Effect_Vectors!$B$2:$R$10,MATCH($A10,Net_Effect_Vectors!$A$2:$A$10,0),COLUMN()-2)=INDEX(Net_Effect_Vectors!$B$2:$R$10,MATCH($B10,Net_Effect_Vectors!$A$2:$A$10,0),COLUMN()-2),0,IF(OR(INDEX(Net_Effect_Vectors!$B$2:$R$10,MATCH($A10,Net_Effect_Vectors!$A$2:$A$10,0),COLUMN()-2)="~",INDEX(Net_Effect_Vectors!$B$2:$R$10,MATCH($B10,Net_Effect_Vectors!$A$2:$A$10,0),COLUMN()-2)="~"),1,2)) -> 2 | I10: =IF(INDEX(Net_Effect_Vectors!$B$2:$R$10,MATCH($A10,Net_Effect_Vectors!$A$2:$A$10,0),COLUMN()-2)=INDEX(Net_Effect_Vectors!$B$2:$R$10,MATCH($B10,Net_Effect_Vectors!$A$2:$A$10,0),COLUMN()-2),0,IF(OR(INDEX(Net_Effect_Vectors!$B$2:$R$10,MATCH($A10,Net_Effect_Vectors!$A$2:$A$10,0),COLUMN()-2)="~",INDEX(Net_Effect_Vectors!$B$2:$R$10,MATCH($B10,Net_Effect_Vectors!$A$2:$A$10,0),COLUMN()-2)="~"),1,2)) -> 2 | J10: =IF(INDEX(Net_Effect_Vectors!$B$2:$R$10,MATCH($A10,Net_Effect_Vectors!$A$2:$A$10,0),COLUMN()-2)=INDEX(Net_Effect_Vectors!$B$2:$R$10,MATCH($B10,Net_Effect_Vectors!$A$2:$A$10,0),COLUMN()-2),0,IF(OR(INDEX(Net_Effect_Vectors!$B$2:$R$10,MATCH($A10,Net_Effect_Vectors!$A$2:$A$10,0),COLUMN()-2)="~",INDEX(Net_Effect_Vectors!$B$2:$R$10,MATCH($B10,Net_Effect_Vectors!$A$2:$A$10,0),COLUMN()-2)="~"),1,2)) -> 1 | ... S10: =IF(INDEX(Net_Effect_Vectors!$B$2:$R$10,MATCH($A10,Net_Effect_Vectors!$A$2:$A$10,0),COLUMN()-2)=INDEX(Net_Effect_Vectors!$B$2:$R$10,MATCH($B10,Net_Effect_Vectors!$A$2:$A$10,0),COLUMN()-2),0,IF(OR(INDEX(Net_Effect_Vectors!$B$2:$R$10,MATCH($A10,Net_Effect_Vectors!$A$2:$A$10,0),COLUMN()-2)="~",INDEX(Net_Effect_Vectors!$B$2:$R$10,MATCH($B10,Net_Effect_Vectors!$A$2:$A$10,0),COLUMN()-2)="~"),1,2)) -> 0 | T10: =SUM(C10:S10) -> 24 | U10: =ROUND(100*(1-T10/34),1) -> 29.4 | V10: =IF(U10>=80,"HIGH COMPATIBILITY",IF(U10>=65,"MODERATE-HIGH",IF(U10>=50,"MODERATE",IF(U10>=35,"MODERATE-LOW","HIGH RISK")))) -> HIGH RISK | W10: CANON (reproduced)
A11: NF/SFJ | B11: NT/STJ | C11: =IF(INDEX(Net_Effect_Vectors!$B$2:$R$10,MATCH($A11,Net_Effect_Vectors!$A$2:$A$10,0),COLUMN()-2)=INDEX(Net_Effect_Vectors!$B$2:$R$10,MATCH($B11,Net_Effect_Vectors!$A$2:$A$10,0),COLUMN()-2),0,IF(OR(INDEX(Net_Effect_Vectors!$B$2:$R$10,MATCH($A11,Net_Effect_Vectors!$A$2:$A$10,0),COLUMN()-2)="~",INDEX(Net_Effect_Vectors!$B$2:$R$10,MATCH($B11,Net_Effect_Vectors!$A$2:$A$10,0),COLUMN()-2)="~"),1,2)) -> 2 | D11: =IF(INDEX(Net_Effect_Vectors!$B$2:$R$10,MATCH($A11,Net_Effect_Vectors!$A$2:$A$10,0),COLUMN()-2)=INDEX(Net_Effect_Vectors!$B$2:$R$10,MATCH($B11,Net_Effect_Vectors!$A$2:$A$10,0),COLUMN()-2),0,IF(OR(INDEX(Net_Effect_Vectors!$B$2:$R$10,MATCH($A11,Net_Effect_Vectors!$A$2:$A$10,0),COLUMN()-2)="~",INDEX(Net_Effect_Vectors!$B$2:$R$10,MATCH($B11,Net_Effect_Vectors!$A$2:$A$10,0),COLUMN()-2)="~"),1,2)) -> 2 | E11: =IF(INDEX(Net_Effect_Vectors!$B$2:$R$10,MATCH($A11,Net_Effect_Vectors!$A$2:$A$10,0),COLUMN()-2)=INDEX(Net_Effect_Vectors!$B$2:$R$10,MATCH($B11,Net_Effect_Vectors!$A$2:$A$10,0),COLUMN()-2),0,IF(OR(INDEX(Net_Effect_Vectors!$B$2:$R$10,MATCH($A11,Net_Effect_Vectors!$A$2:$A$10,0),COLUMN()-2)="~",INDEX(Net_Effect_Vectors!$B$2:$R$10,MATCH($B11,Net_Effect_Vectors!$A$2:$A$10,0),COLUMN()-2)="~"),1,2)) -> 2 | F11: =IF(INDEX(Net_Effect_Vectors!$B$2:$R$10,MATCH($A11,Net_Effect_Vectors!$A$2:$A$10,0),COLUMN()-2)=INDEX(Net_Effect_Vectors!$B$2:$R$10,MATCH($B11,Net_Effect_Vectors!$A$2:$A$10,0),COLUMN()-2),0,IF(OR(INDEX(Net_Effect_Vectors!$B$2:$R$10,MATCH($A11,Net_Effect_Vectors!$A$2:$A$10,0),COLUMN()-2)="~",INDEX(Net_Effect_Vectors!$B$2:$R$10,MATCH($B11,Net_Effect_Vectors!$A$2:$A$10,0),COLUMN()-2)="~"),1,2)) -> 2 | G11: =IF(INDEX(Net_Effect_Vectors!$B$2:$R$10,MATCH($A11,Net_Effect_Vectors!$A$2:$A$10,0),COLUMN()-2)=INDEX(Net_Effect_Vectors!$B$2:$R$10,MATCH($B11,Net_Effect_Vectors!$A$2:$A$10,0),COLUMN()-2),0,IF(OR(INDEX(Net_Effect_Vectors!$B$2:$R$10,MATCH($A11,Net_Effect_Vectors!$A$2:$A$10,0),COLUMN()-2)="~",INDEX(Net_Effect_Vectors!$B$2:$R$10,MATCH($B11,Net_Effect_Vectors!$A$2:$A$10,0),COLUMN()-2)="~"),1,2)) -> 1 | H11: =IF(INDEX(Net_Effect_Vectors!$B$2:$R$10,MATCH($A11,Net_Effect_Vectors!$A$2:$A$10,0),COLUMN()-2)=INDEX(Net_Effect_Vectors!$B$2:$R$10,MATCH($B11,Net_Effect_Vectors!$A$2:$A$10,0),COLUMN()-2),0,IF(OR(INDEX(Net_Effect_Vectors!$B$2:$R$10,MATCH($A11,Net_Effect_Vectors!$A$2:$A$10,0),COLUMN()-2)="~",INDEX(Net_Effect_Vectors!$B$2:$R$10,MATCH($B11,Net_Effect_Vectors!$A$2:$A$10,0),COLUMN()-2)="~"),1,2)) -> 1 | I11: =IF(INDEX(Net_Effect_Vectors!$B$2:$R$10,MATCH($A11,Net_Effect_Vectors!$A$2:$A$10,0),COLUMN()-2)=INDEX(Net_Effect_Vectors!$B$2:$R$10,MATCH($B11,Net_Effect_Vectors!$A$2:$A$10,0),COLUMN()-2),0,IF(OR(INDEX(Net_Effect_Vectors!$B$2:$R$10,MATCH($A11,Net_Effect_Vectors!$A$2:$A$10,0),COLUMN()-2)="~",INDEX(Net_Effect_Vectors!$B$2:$R$10,MATCH($B11,Net_Effect_Vectors!$A$2:$A$10,0),COLUMN()-2)="~"),1,2)) -> 2 | J11: =IF(INDEX(Net_Effect_Vectors!$B$2:$R$10,MATCH($A11,Net_Effect_Vectors!$A$2:$A$10,0),COLUMN()-2)=INDEX(Net_Effect_Vectors!$B$2:$R$10,MATCH($B11,Net_Effect_Vectors!$A$2:$A$10,0),COLUMN()-2),0,IF(OR(INDEX(Net_Effect_Vectors!$B$2:$R$10,MATCH($A11,Net_Effect_Vectors!$A$2:$A$10,0),COLUMN()-2)="~",INDEX(Net_Effect_Vectors!$B$2:$R$10,MATCH($B11,Net_Effect_Vectors!$A$2:$A$10,0),COLUMN()-2)="~"),1,2)) -> 2 | ... S11: =IF(INDEX(Net_Effect_Vectors!$B$2:$R$10,MATCH($A11,Net_Effect_Vectors!$A$2:$A$10,0),COLUMN()-2)=INDEX(Net_Effect_Vectors!$B$2:$R$10,MATCH($B11,Net_Effect_Vectors!$A$2:$A$10,0),COLUMN()-2),0,IF(OR(INDEX(Net_Effect_Vectors!$B$2:$R$10,MATCH($A11,Net_Effect_Vectors!$A$2:$A$10,0),COLUMN()-2)="~",INDEX(Net_Effect_Vectors!$B$2:$R$10,MATCH($B11,Net_Effect_Vectors!$A$2:$A$10,0),COLUMN()-2)="~"),1,2)) -> 2 | T11: =SUM(C11:S11) -> 29 | U11: =ROUND(100*(1-T11/34),1) -> 14.7 | V11: =IF(U11>=80,"HIGH COMPATIBILITY",IF(U11>=65,"MODERATE-HIGH",IF(U11>=50,"MODERATE",IF(U11>=35,"MODERATE-LOW","HIGH RISK")))) -> HIGH RISK | W11: CANON (reproduced)
A12: NF/SFJ | B12: NT/STP | C12: =IF(INDEX(Net_Effect_Vectors!$B$2:$R$10,MATCH($A12,Net_Effect_Vectors!$A$2:$A$10,0),COLUMN()-2)=INDEX(Net_Effect_Vectors!$B$2:$R$10,MATCH($B12,Net_Effect_Vectors!$A$2:$A$10,0),COLUMN()-2),0,IF(OR(INDEX(Net_Effect_Vectors!$B$2:$R$10,MATCH($A12,Net_Effect_Vectors!$A$2:$A$10,0),COLUMN()-2)="~",INDEX(Net_Effect_Vectors!$B$2:$R$10,MATCH($B12,Net_Effect_Vectors!$A$2:$A$10,0),COLUMN()-2)="~"),1,2)) -> 1 | D12: =IF(INDEX(Net_Effect_Vectors!$B$2:$R$10,MATCH($A12,Net_Effect_Vectors!$A$2:$A$10,0),COLUMN()-2)=INDEX(Net_Effect_Vectors!$B$2:$R$10,MATCH($B12,Net_Effect_Vectors!$A$2:$A$10,0),COLUMN()-2),0,IF(OR(INDEX(Net_Effect_Vectors!$B$2:$R$10,MATCH($A12,Net_Effect_Vectors!$A$2:$A$10,0),COLUMN()-2)="~",INDEX(Net_Effect_Vectors!$B$2:$R$10,MATCH($B12,Net_Effect_Vectors!$A$2:$A$10,0),COLUMN()-2)="~"),1,2)) -> 2 | E12: =IF(INDEX(Net_Effect_Vectors!$B$2:$R$10,MATCH($A12,Net_Effect_Vectors!$A$2:$A$10,0),COLUMN()-2)=INDEX(Net_Effect_Vectors!$B$2:$R$10,MATCH($B12,Net_Effect_Vectors!$A$2:$A$10,0),COLUMN()-2),0,IF(OR(INDEX(Net_Effect_Vectors!$B$2:$R$10,MATCH($A12,Net_Effect_Vectors!$A$2:$A$10,0),COLUMN()-2)="~",INDEX(Net_Effect_Vectors!$B$2:$R$10,MATCH($B12,Net_Effect_Vectors!$A$2:$A$10,0),COLUMN()-2)="~"),1,2)) -> 2 | F12: =IF(INDEX(Net_Effect_Vectors!$B$2:$R$10,MATCH($A12,Net_Effect_Vectors!$A$2:$A$10,0),COLUMN()-2)=INDEX(Net_Effect_Vectors!$B$2:$R$10,MATCH($B12,Net_Effect_Vectors!$A$2:$A$10,0),COLUMN()-2),0,IF(OR(INDEX(Net_Effect_Vectors!$B$2:$R$10,MATCH($A12,Net_Effect_Vectors!$A$2:$A$10,0),COLUMN()-2)="~",INDEX(Net_Effect_Vectors!$B$2:$R$10,MATCH($B12,Net_Effect_Vectors!$A$2:$A$10,0),COLUMN()-2)="~"),1,2)) -> 1 | G12: =IF(INDEX(Net_Effect_Vectors!$B$2:$R$10,MATCH($A12,Net_Effect_Vectors!$A$2:$A$10,0),COLUMN()-2)=INDEX(Net_Effect_Vectors!$B$2:$R$10,MATCH($B12,Net_Effect_Vectors!$A$2:$A$10,0),COLUMN()-2),0,IF(OR(INDEX(Net_Effect_Vectors!$B$2:$R$10,MATCH($A12,Net_Effect_Vectors!$A$2:$A$10,0),COLUMN()-2)="~",INDEX(Net_Effect_Vectors!$B$2:$R$10,MATCH($B12,Net_Effect_Vectors!$A$2:$A$10,0),COLUMN()-2)="~"),1,2)) -> 1 | H12: =IF(INDEX(Net_Effect_Vectors!$B$2:$R$10,MATCH($A12,Net_Effect_Vectors!$A$2:$A$10,0),COLUMN()-2)=INDEX(Net_Effect_Vectors!$B$2:$R$10,MATCH($B12,Net_Effect_Vectors!$A$2:$A$10,0),COLUMN()-2),0,IF(OR(INDEX(Net_Effect_Vectors!$B$2:$R$10,MATCH($A12,Net_Effect_Vectors!$A$2:$A$10,0),COLUMN()-2)="~",INDEX(Net_Effect_Vectors!$B$2:$R$10,MATCH($B12,Net_Effect_Vectors!$A$2:$A$10,0),COLUMN()-2)="~"),1,2)) -> 1 | I12: =IF(INDEX(Net_Effect_Vectors!$B$2:$R$10,MATCH($A12,Net_Effect_Vectors!$A$2:$A$10,0),COLUMN()-2)=INDEX(Net_Effect_Vectors!$B$2:$R$10,MATCH($B12,Net_Effect_Vectors!$A$2:$A$10,0),COLUMN()-2),0,IF(OR(INDEX(Net_Effect_Vectors!$B$2:$R$10,MATCH($A12,Net_Effect_Vectors!$A$2:$A$10,0),COLUMN()-2)="~",INDEX(Net_Effect_Vectors!$B$2:$R$10,MATCH($B12,Net_Effect_Vectors!$A$2:$A$10,0),COLUMN()-2)="~"),1,2)) -> 2 | J12: =IF(INDEX(Net_Effect_Vectors!$B$2:$R$10,MATCH($A12,Net_Effect_Vectors!$A$2:$A$10,0),COLUMN()-2)=INDEX(Net_Effect_Vectors!$B$2:$R$10,MATCH($B12,Net_Effect_Vectors!$A$2:$A$10,0),COLUMN()-2),0,IF(OR(INDEX(Net_Effect_Vectors!$B$2:$R$10,MATCH($A12,Net_Effect_Vectors!$A$2:$A$10,0),COLUMN()-2)="~",INDEX(Net_Effect_Vectors!$B$2:$R$10,MATCH($B12,Net_Effect_Vectors!$A$2:$A$10,0),COLUMN()-2)="~"),1,2)) -> 2 | ... S12: =IF(INDEX(Net_Effect_Vectors!$B$2:$R$10,MATCH($A12,Net_Effect_Vectors!$A$2:$A$10,0),COLUMN()-2)=INDEX(Net_Effect_Vectors!$B$2:$R$10,MATCH($B12,Net_Effect_Vectors!$A$2:$A$10,0),COLUMN()-2),0,IF(OR(INDEX(Net_Effect_Vectors!$B$2:$R$10,MATCH($A12,Net_Effect_Vectors!$A$2:$A$10,0),COLUMN()-2)="~",INDEX(Net_Effect_Vectors!$B$2:$R$10,MATCH($B12,Net_Effect_Vectors!$A$2:$A$10,0),COLUMN()-2)="~"),1,2)) -> 1 | T12: =SUM(C12:S12) -> 26 | U12: =ROUND(100*(1-T12/34),1) -> 23.5 | V12: =IF(U12>=80,"HIGH COMPATIBILITY",IF(U12>=65,"MODERATE-HIGH",IF(U12>=50,"MODERATE",IF(U12>=35,"MODERATE-LOW","HIGH RISK")))) -> HIGH RISK | W12: CANON (reproduced)
A13: NF/SFJ | B13: SFJ/SFP | C13: =IF(INDEX(Net_Effect_Vectors!$B$2:$R$10,MATCH($A13,Net_Effect_Vectors!$A$2:$A$10,0),COLUMN()-2)=INDEX(Net_Effect_Vectors!$B$2:$R$10,MATCH($B13,Net_Effect_Vectors!$A$2:$A$10,0),COLUMN()-2),0,IF(OR(INDEX(Net_Effect_Vectors!$B$2:$R$10,MATCH($A13,Net_Effect_Vectors!$A$2:$A$10,0),COLUMN()-2)="~",INDEX(Net_Effect_Vectors!$B$2:$R$10,MATCH($B13,Net_Effect_Vectors!$A$2:$A$10,0),COLUMN()-2)="~"),1,2)) -> 2 | D13: =IF(INDEX(Net_Effect_Vectors!$B$2:$R$10,MATCH($A13,Net_Effect_Vectors!$A$2:$A$10,0),COLUMN()-2)=INDEX(Net_Effect_Vectors!$B$2:$R$10,MATCH($B13,Net_Effect_Vectors!$A$2:$A$10,0),COLUMN()-2),0,IF(OR(INDEX(Net_Effect_Vectors!$B$2:$R$10,MATCH($A13,Net_Effect_Vectors!$A$2:$A$10,0),COLUMN()-2)="~",INDEX(Net_Effect_Vectors!$B$2:$R$10,MATCH($B13,Net_Effect_Vectors!$A$2:$A$10,0),COLUMN()-2)="~"),1,2)) -> 2 | E13: =IF(INDEX(Net_Effect_Vectors!$B$2:$R$10,MATCH($A13,Net_Effect_Vectors!$A$2:$A$10,0),COLUMN()-2)=INDEX(Net_Effect_Vectors!$B$2:$R$10,MATCH($B13,Net_Effect_Vectors!$A$2:$A$10,0),COLUMN()-2),0,IF(OR(INDEX(Net_Effect_Vectors!$B$2:$R$10,MATCH($A13,Net_Effect_Vectors!$A$2:$A$10,0),COLUMN()-2)="~",INDEX(Net_Effect_Vectors!$B$2:$R$10,MATCH($B13,Net_Effect_Vectors!$A$2:$A$10,0),COLUMN()-2)="~"),1,2)) -> 2 | F13: =IF(INDEX(Net_Effect_Vectors!$B$2:$R$10,MATCH($A13,Net_Effect_Vectors!$A$2:$A$10,0),COLUMN()-2)=INDEX(Net_Effect_Vectors!$B$2:$R$10,MATCH($B13,Net_Effect_Vectors!$A$2:$A$10,0),COLUMN()-2),0,IF(OR(INDEX(Net_Effect_Vectors!$B$2:$R$10,MATCH($A13,Net_Effect_Vectors!$A$2:$A$10,0),COLUMN()-2)="~",INDEX(Net_Effect_Vectors!$B$2:$R$10,MATCH($B13,Net_Effect_Vectors!$A$2:$A$10,0),COLUMN()-2)="~"),1,2)) -> 2 | G13: =IF(INDEX(Net_Effect_Vectors!$B$2:$R$10,MATCH($A13,Net_Effect_Vectors!$A$2:$A$10,0),COLUMN()-2)=INDEX(Net_Effect_Vectors!$B$2:$R$10,MATCH($B13,Net_Effect_Vectors!$A$2:$A$10,0),COLUMN()-2),0,IF(OR(INDEX(Net_Effect_Vectors!$B$2:$R$10,MATCH($A13,Net_Effect_Vectors!$A$2:$A$10,0),COLUMN()-2)="~",INDEX(Net_Effect_Vectors!$B$2:$R$10,MATCH($B13,Net_Effect_Vectors!$A$2:$A$10,0),COLUMN()-2)="~"),1,2)) -> 1 | H13: =IF(INDEX(Net_Effect_Vectors!$B$2:$R$10,MATCH($A13,Net_Effect_Vectors!$A$2:$A$10,0),COLUMN()-2)=INDEX(Net_Effect_Vectors!$B$2:$R$10,MATCH($B13,Net_Effect_Vectors!$A$2:$A$10,0),COLUMN()-2),0,IF(OR(INDEX(Net_Effect_Vectors!$B$2:$R$10,MATCH($A13,Net_Effect_Vectors!$A$2:$A$10,0),COLUMN()-2)="~",INDEX(Net_Effect_Vectors!$B$2:$R$10,MATCH($B13,Net_Effect_Vectors!$A$2:$A$10,0),COLUMN()-2)="~"),1,2)) -> 2 | I13: =IF(INDEX(Net_Effect_Vectors!$B$2:$R$10,MATCH($A13,Net_Effect_Vectors!$A$2:$A$10,0),COLUMN()-2)=INDEX(Net_Effect_Vectors!$B$2:$R$10,MATCH($B13,Net_Effect_Vectors!$A$2:$A$10,0),COLUMN()-2),0,IF(OR(INDEX(Net_Effect_Vectors!$B$2:$R$10,MATCH($A13,Net_Effect_Vectors!$A$2:$A$10,0),COLUMN()-2)="~",INDEX(Net_Effect_Vectors!$B$2:$R$10,MATCH($B13,Net_Effect_Vectors!$A$2:$A$10,0),COLUMN()-2)="~"),1,2)) -> 2 | J13: =IF(INDEX(Net_Effect_Vectors!$B$2:$R$10,MATCH($A13,Net_Effect_Vectors!$A$2:$A$10,0),COLUMN()-2)=INDEX(Net_Effect_Vectors!$B$2:$R$10,MATCH($B13,Net_Effect_Vectors!$A$2:$A$10,0),COLUMN()-2),0,IF(OR(INDEX(Net_Effect_Vectors!$B$2:$R$10,MATCH($A13,Net_Effect_Vectors!$A$2:$A$10,0),COLUMN()-2)="~",INDEX(Net_Effect_Vectors!$B$2:$R$10,MATCH($B13,Net_Effect_Vectors!$A$2:$A$10,0),COLUMN()-2)="~"),1,2)) -> 1 | ... S13: =IF(INDEX(Net_Effect_Vectors!$B$2:$R$10,MATCH($A13,Net_Effect_Vectors!$A$2:$A$10,0),COLUMN()-2)=INDEX(Net_Effect_Vectors!$B$2:$R$10,MATCH($B13,Net_Effect_Vectors!$A$2:$A$10,0),COLUMN()-2),0,IF(OR(INDEX(Net_Effect_Vectors!$B$2:$R$10,MATCH($A13,Net_Effect_Vectors!$A$2:$A$10,0),COLUMN()-2)="~",INDEX(Net_Effect_Vectors!$B$2:$R$10,MATCH($B13,Net_Effect_Vectors!$A$2:$A$10,0),COLUMN()-2)="~"),1,2)) -> 0 | T13: =SUM(C13:S13) -> 21 | U13: =ROUND(100*(1-T13/34),1) -> 38.2 | V13: =IF(U13>=80,"HIGH COMPATIBILITY",IF(U13>=65,"MODERATE-HIGH",IF(U13>=50,"MODERATE",IF(U13>=35,"MODERATE-LOW","HIGH RISK")))) -> MODERATE-LOW | W13: CANON (reproduced)
... A37: STJ/STP | B37: STP/STJ | C37: =IF(INDEX(Net_Effect_Vectors!$B$2:$R$10,MATCH($A37,Net_Effect_Vectors!$A$2:$A$10,0),COLUMN()-2)=INDEX(Net_Effect_Vectors!$B$2:$R$10,MATCH($B37,Net_Effect_Vectors!$A$2:$A$10,0),COLUMN()-2),0,IF(OR(INDEX(Net_Effect_Vectors!$B$2:$R$10,MATCH($A37,Net_Effect_Vectors!$A$2:$A$10,0),COLUMN()-2)="~",INDEX(Net_Effect_Vectors!$B$2:$R$10,MATCH($B37,Net_Effect_Vectors!$A$2:$A$10,0),COLUMN()-2)="~"),1,2)) -> 0 | D37: =IF(INDEX(Net_Effect_Vectors!$B$2:$R$10,MATCH($A37,Net_Effect_Vectors!$A$2:$A$10,0),COLUMN()-2)=INDEX(Net_Effect_Vectors!$B$2:$R$10,MATCH($B37,Net_Effect_Vectors!$A$2:$A$10,0),COLUMN()-2),0,IF(OR(INDEX(Net_Effect_Vectors!$B$2:$R$10,MATCH($A37,Net_Effect_Vectors!$A$2:$A$10,0),COLUMN()-2)="~",INDEX(Net_Effect_Vectors!$B$2:$R$10,MATCH($B37,Net_Effect_Vectors!$A$2:$A$10,0),COLUMN()-2)="~"),1,2)) -> 0 | E37: =IF(INDEX(Net_Effect_Vectors!$B$2:$R$10,MATCH($A37,Net_Effect_Vectors!$A$2:$A$10,0),COLUMN()-2)=INDEX(Net_Effect_Vectors!$B$2:$R$10,MATCH($B37,Net_Effect_Vectors!$A$2:$A$10,0),COLUMN()-2),0,IF(OR(INDEX(Net_Effect_Vectors!$B$2:$R$10,MATCH($A37,Net_Effect_Vectors!$A$2:$A$10,0),COLUMN()-2)="~",INDEX(Net_Effect_Vectors!$B$2:$R$10,MATCH($B37,Net_Effect_Vectors!$A$2:$A$10,0),COLUMN()-2)="~"),1,2)) -> 1 | F37: =IF(INDEX(Net_Effect_Vectors!$B$2:$R$10,MATCH($A37,Net_Effect_Vectors!$A$2:$A$10,0),COLUMN()-2)=INDEX(Net_Effect_Vectors!$B$2:$R$10,MATCH($B37,Net_Effect_Vectors!$A$2:$A$10,0),COLUMN()-2),0,IF(OR(INDEX(Net_Effect_Vectors!$B$2:$R$10,MATCH($A37,Net_Effect_Vectors!$A$2:$A$10,0),COLUMN()-2)="~",INDEX(Net_Effect_Vectors!$B$2:$R$10,MATCH($B37,Net_Effect_Vectors!$A$2:$A$10,0),COLUMN()-2)="~"),1,2)) -> 0 | G37: =IF(INDEX(Net_Effect_Vectors!$B$2:$R$10,MATCH($A37,Net_Effect_Vectors!$A$2:$A$10,0),COLUMN()-2)=INDEX(Net_Effect_Vectors!$B$2:$R$10,MATCH($B37,Net_Effect_Vectors!$A$2:$A$10,0),COLUMN()-2),0,IF(OR(INDEX(Net_Effect_Vectors!$B$2:$R$10,MATCH($A37,Net_Effect_Vectors!$A$2:$A$10,0),COLUMN()-2)="~",INDEX(Net_Effect_Vectors!$B$2:$R$10,MATCH($B37,Net_Effect_Vectors!$A$2:$A$10,0),COLUMN()-2)="~"),1,2)) -> 0 | H37: =IF(INDEX(Net_Effect_Vectors!$B$2:$R$10,MATCH($A37,Net_Effect_Vectors!$A$2:$A$10,0),COLUMN()-2)=INDEX(Net_Effect_Vectors!$B$2:$R$10,MATCH($B37,Net_Effect_Vectors!$A$2:$A$10,0),COLUMN()-2),0,IF(OR(INDEX(Net_Effect_Vectors!$B$2:$R$10,MATCH($A37,Net_Effect_Vectors!$A$2:$A$10,0),COLUMN()-2)="~",INDEX(Net_Effect_Vectors!$B$2:$R$10,MATCH($B37,Net_Effect_Vectors!$A$2:$A$10,0),COLUMN()-2)="~"),1,2)) -> 0 | I37: =IF(INDEX(Net_Effect_Vectors!$B$2:$R$10,MATCH($A37,Net_Effect_Vectors!$A$2:$A$10,0),COLUMN()-2)=INDEX(Net_Effect_Vectors!$B$2:$R$10,MATCH($B37,Net_Effect_Vectors!$A$2:$A$10,0),COLUMN()-2),0,IF(OR(INDEX(Net_Effect_Vectors!$B$2:$R$10,MATCH($A37,Net_Effect_Vectors!$A$2:$A$10,0),COLUMN()-2)="~",INDEX(Net_Effect_Vectors!$B$2:$R$10,MATCH($B37,Net_Effect_Vectors!$A$2:$A$10,0),COLUMN()-2)="~"),1,2)) -> 0 | J37: =IF(INDEX(Net_Effect_Vectors!$B$2:$R$10,MATCH($A37,Net_Effect_Vectors!$A$2:$A$10,0),COLUMN()-2)=INDEX(Net_Effect_Vectors!$B$2:$R$10,MATCH($B37,Net_Effect_Vectors!$A$2:$A$10,0),COLUMN()-2),0,IF(OR(INDEX(Net_Effect_Vectors!$B$2:$R$10,MATCH($A37,Net_Effect_Vectors!$A$2:$A$10,0),COLUMN()-2)="~",INDEX(Net_Effect_Vectors!$B$2:$R$10,MATCH($B37,Net_Effect_Vectors!$A$2:$A$10,0),COLUMN()-2)="~"),1,2)) -> 0 | ... S37: =IF(INDEX(Net_Effect_Vectors!$B$2:$R$10,MATCH($A37,Net_Effect_Vectors!$A$2:$A$10,0),COLUMN()-2)=INDEX(Net_Effect_Vectors!$B$2:$R$10,MATCH($B37,Net_Effect_Vectors!$A$2:$A$10,0),COLUMN()-2),0,IF(OR(INDEX(Net_Effect_Vectors!$B$2:$R$10,MATCH($A37,Net_Effect_Vectors!$A$2:$A$10,0),COLUMN()-2)="~",INDEX(Net_Effect_Vectors!$B$2:$R$10,MATCH($B37,Net_Effect_Vectors!$A$2:$A$10,0),COLUMN()-2)="~"),1,2)) -> 0 | T37: =SUM(C37:S37) -> 3 | U37: =ROUND(100*(1-T37/34),1) -> 91.2 | V37: =IF(U37>=80,"HIGH COMPATIBILITY",IF(U37>=65,"MODERATE-HIGH",IF(U37>=50,"MODERATE",IF(U37>=35,"MODERATE-LOW","HIGH RISK")))) -> HIGH COMPATIBILITY | W37: CANON (author-canonized June 2026)
A39: Same-environment pairs (diagonal) = 100 by definition (●), not computed. STP/STJ values author-canonized June 2026 and published in ST_Friction_Point_Lookup_updated.xlsx → ECS_Matrix (9×9).

Sheet Reproduction_Test
A1: Env A | B1: Env B | C1: Published ECS (source: ST_Friction_Point_Lookup_updated.xlsx → ECS_Matrix) | D1: Computed ECS (link) | E1: Diff | F1: Result
A2: NF/NT | B2: NF/SFJ | C2: 17.6 | D2: =Pair_Computation!U2 -> 17.6 | E2: =ROUND(D2-C2,1) -> 0 | F2: =IF(E2=0,"PASS","FAIL") -> PASS
A3: NF/NT | B3: NF/SFP | C3: 82.4 | D3: =Pair_Computation!U3 -> 82.4 | E3: =ROUND(D3-C3,1) -> 0 | F3: =IF(E3=0,"PASS","FAIL") -> PASS
A4: NF/NT | B4: NT/STJ | C4: 85.3 | D4: =Pair_Computation!U4 -> 85.3 | E4: =ROUND(D4-C4,1) -> 0 | F4: =IF(E4=0,"PASS","FAIL") -> PASS
A5: NF/NT | B5: NT/STP | C5: 88.2 | D5: =Pair_Computation!U5 -> 88.2 | E5: =ROUND(D5-C5,1) -> 0 | F5: =IF(E5=0,"PASS","FAIL") -> PASS
A6: NF/NT | B6: SFJ/SFP | C6: 67.6 | D6: =Pair_Computation!U6 -> 67.6 | E6: =ROUND(D6-C6,1) -> 0 | F6: =IF(E6=0,"PASS","FAIL") -> PASS
A7: NF/NT | B7: SFP/SFJ | C7: 17.6 | D7: =Pair_Computation!U7 -> 17.6 | E7: =ROUND(D7-C7,1) -> 0 | F7: =IF(E7=0,"PASS","FAIL") -> PASS
A8: NF/NT | B8: STJ/STP | C8: 61.8 | D8: =Pair_Computation!U8 -> 61.8 | E8: =ROUND(D8-C8,1) -> 0 | F8: =IF(E8=0,"PASS","FAIL") -> PASS
A9: NF/SFJ | B9: NF/SFP | C9: 29.4 | D9: =Pair_Computation!U10 -> 29.4 | E9: =ROUND(D9-C9,1) -> 0 | F9: =IF(E9=0,"PASS","FAIL") -> PASS
A10: NF/SFJ | B10: NT/STJ | C10: 14.7 | D10: =Pair_Computation!U11 -> 14.7 | E10: =ROUND(D10-C10,1) -> 0 | F10: =IF(E10=0,"PASS","FAIL") -> PASS
A11: NF/SFJ | B11: NT/STP | C11: 23.5 | D11: =Pair_Computation!U12 -> 23.5 | E11: =ROUND(D11-C11,1) -> 0 | F11: =IF(E11=0,"PASS","FAIL") -> PASS
A12: NF/SFJ | B12: SFJ/SFP | C12: 38.2 | D12: =Pair_Computation!U13 -> 38.2 | E12: =ROUND(D12-C12,1) -> 0 | F12: =IF(E12=0,"PASS","FAIL") -> PASS
A13: NF/SFJ | B13: SFP/SFJ | C13: 88.2 | D13: =Pair_Computation!U14 -> 88.2 | E13: =ROUND(D13-C13,1) -> 0 | F13: =IF(E13=0,"PASS","FAIL") -> PASS
A14: NF/SFJ | B14: STJ/STP | C14: 38.2 | D14: =Pair_Computation!U15 -> 38.2 | E14: =ROUND(D14-C14,1) -> 0 | F14: =IF(E14=0,"PASS","FAIL") -> PASS
A15: NF/SFP | B15: NT/STJ | C15: 67.6 | D15: =Pair_Computation!U17 -> 67.6 | E15: =ROUND(D15-C15,1) -> 0 | F15: =IF(E15=0,"PASS","FAIL") -> PASS
A16: NF/SFP | B16: NT/STP | C16: 76.5 | D16: =Pair_Computation!U18 -> 76.5 | E16: =ROUND(D16-C16,1) -> 0 | F16: =IF(E16=0,"PASS","FAIL") -> PASS
A17: NF/SFP | B17: SFJ/SFP | C17: 79.4 | D17: =Pair_Computation!U19 -> 79.4 | E17: =ROUND(D17-C17,1) -> 0 | F17: =IF(E17=0,"PASS","FAIL") -> PASS
A18: NF/SFP | B18: SFP/SFJ | C18: 23.5 | D18: =Pair_Computation!U20 -> 23.5 | E18: =ROUND(D18-C18,1) -> 0 | F18: =IF(E18=0,"PASS","FAIL") -> PASS
A19: NF/SFP | B19: STJ/STP | C19: 61.8 | D19: =Pair_Computation!U21 -> 61.8 | E19: =ROUND(D19-C19,1) -> 0 | F19: =IF(E19=0,"PASS","FAIL") -> PASS
A20: NT/STJ | B20: NT/STP | C20: 91.2 | D20: =Pair_Computation!U23 -> 91.2 | E20: =ROUND(D20-C20,1) -> 0 | F20: =IF(E20=0,"PASS","FAIL") -> PASS
A21: NT/STJ | B21: SFJ/SFP | C21: 58.8 | D21: =Pair_Computation!U24 -> 58.8 | E21: =ROUND(D21-C21,1) -> 0 | F21: =IF(E21=0,"PASS","FAIL") -> PASS
A22: NT/STJ | B22: SFP/SFJ | C22: 14.7 | D22: =Pair_Computation!U25 -> 14.7 | E22: =ROUND(D22-C22,1) -> 0 | F22: =IF(E22=0,"PASS","FAIL") -> PASS
A23: NT/STJ | B23: STJ/STP | C23: 76.5 | D23: =Pair_Computation!U26 -> 76.5 | E23: =ROUND(D23-C23,1) -> 0 | F23: =IF(E23=0,"PASS","FAIL") -> PASS
A24: NT/STP | B24: SFJ/SFP | C24: 55.9 | D24: =Pair_Computation!U28 -> 55.9 | E24: =ROUND(D24-C24,1) -> 0 | F24: =IF(E24=0,"PASS","FAIL") -> PASS
A25: NT/STP | B25: SFP/SFJ | C25: 23.5 | D25: =Pair_Computation!U29 -> 23.5 | E25: =ROUND(D25-C25,1) -> 0 | F25: =IF(E25=0,"PASS","FAIL") -> PASS
A26: NT/STP | B26: STJ/STP | C26: 73.5 | D26: =Pair_Computation!U30 -> 73.5 | E26: =ROUND(D26-C26,1) -> 0 | F26: =IF(E26=0,"PASS","FAIL") -> PASS
A27: SFJ/SFP | B27: SFP/SFJ | C27: 32.4 | D27: =Pair_Computation!U32 -> 32.4 | E27: =ROUND(D27-C27,1) -> 0 | F27: =IF(E27=0,"PASS","FAIL") -> PASS
A28: SFJ/SFP | B28: STJ/STP | C28: 58.8 | D28: =Pair_Computation!U33 -> 58.8 | E28: =ROUND(D28-C28,1) -> 0 | F28: =IF(E28=0,"PASS","FAIL") -> PASS
A29: SFP/SFJ | B29: STJ/STP | C29: 38.2 | D29: =Pair_Computation!U35 -> 38.2 | E29: =ROUND(D29-C29,1) -> 0 | F29: =IF(E29=0,"PASS","FAIL") -> PASS
E30: PASS count: | F30: =COUNTIF(F2:F29,"PASS")&" / 28" -> 28 / 28

Sheet Interpretation_Caveats
A1: SCORE INTERPRETATION RULE — CANONICAL HOME (author decision, June 2026) | B1: This sheet is the canonical location of the ST Score Interpretation Rule. Resolves the deferred canonization question (standalone file vs fold-in) in favour of fold-in: ST_Score_Interpretation_Rule.xlsx will not be created as a separate corpus file. Any draft carrying that name is superseded by this sheet.
